File: text_folda/Al0Si55Ru45_ASR46_896h.ras
*RAS_DATA_START
*RAS_HEADER_START
*DISP_FMT_X "%.2f"
*DISP_FMT_Y "%.0f"
*DISP_FULLSCALE "54580.0000000000"
*DISP_LINE_COLOR "255.0000000000"
*DISP_LINE_STYLE "0.0000000000"
*DISP_LINE_WIDTH "0.2500000000"
*DISP_NOTE "測定データ-23"
*DISP_OFFSET_Y "0.0000000000"
*DISP_PEAKSEARCH_UNIT_Y "cps"
*DISP_RANGE_BOTTOM "0.0000000000"
*DISP_RANGE_LEFT "5.0000000000"
*DISP_RANGE_LOGCUTOFF "0.0100000000"
*DISP_RANGE_RIGHT "90.0000000000"
*DISP_RANGE_TOP "54580.0000000000"
*DISP_SCALE_MODE_Y "0.0000000000"
*DISP_TAB_NAME "2θ/θ"
*DISP_TITLE_Y "強度"
*DISP_UNIT_Y "cps"
*DISP_WINDOW_NAME "MSG_MACROENGINE"
*FILE_COMMENT " "
*FILE_MD5 ""
*FILE_MEMO " "
*FILE_OPERATOR "User1"
*FILE_SAMPLE " "
*FILE_TYPE "RAS_RAW"
*FILE_USERGROUP "システムユーザー"
*FILE_VERSION "1.0000000000"
*HW_ATTACHMENT_ID "ATT0025"
*HW_ATTACHMENT_NAME "標準|Standard"
*HW_COUNTER_ID-0 "CUT0041"
*HW_COUNTER_ID-1 "CUT0020"
*HW_COUNTER_ID-2 ""
*HW_COUNTER_ID-3 "CSL0021"
*HW_COUNTER_ID-4 "CMC0021"
*HW_COUNTER_NAME-0 "D/teX Ultra 250|D/teX Ultra 250"
*HW_COUNTER_NAME-1 "None|None"
*HW_COUNTER_NAME-2 ""
*HW_COUNTER_NAME-3 "BBM|BBM"
*HW_COUNTER_NAME-4 "検出器モノクロメータ|Detector monochromator"
*HW_COUNTER_SELECT_NAME "D/teX Ultra 250|D/teX Ultra 250"
*HW_GONIOMETER_ID "GON0023"
*HW_GONIOMETER_NAME "SmartLab|SmartLab"
*HW_GONIOMETER_RADIUS-0 "90.0"
*HW_GONIOMETER_RADIUS-1 "114.0"
*HW_GONIOMETER_RADIUS-2 "190.0"
*HW_GONIOMETER_RADIUS-3 "300.0"
*HW_GONIOMETER_RADIUS-4 "187.0"
*HW_GONIOMETER_RADIUS-5 "300.0"
*HW_GONIOMETER_RADIUS-6 "113.0"
*HW_GONIOMETER_RADIUS-7 "331.0"
*HW_I_OPT_ID-0 "CBO0023"
*HW_I_OPT_ID-1 "ICR0023"
*HW_I_OPT_ID-2 "ISL0021"
*HW_I_OPT_ID-3 "ISO0021"
*HW_I_OPT_ID-4 "IAD0021"
*HW_I_OPT_ID-5 "IPR0001"
*HW_I_OPT_NAME-0 "オープン-BBユニット|Open-BB unit"
*HW_I_OPT_NAME-1 "標準入射光学ユニット|Standard incident optical unit"
*HW_I_OPT_NAME-2 "標準入射スリットボックス|Standard incident slit box"
*HW_I_OPT_NAME-3 "入射平行スリット|Incident parallel slit"
*HW_I_OPT_NAME-4 "長手制限スリット|Length limiting slit"
*HW_I_OPT_NAME-5 "None|None"
*HW_R_ATTENUATER_AUTOMODE "0"
*HW_R_OPT_ID-0 "RSS0021"
*HW_R_OPT_ID-1 "RCR0023"
*HW_R_OPT_ID-2 "RSO0021"
*HW_R_OPT_ID-3 "RRS0021"
*HW_R_OPT_ID-4 "ATN0021"
*HW_R_OPT_ID-5 "RFL0021"
*HW_R_OPT_ID-6 "RAD0021"
*HW_R_OPT_NAME-0 "標準受光スリットボックス1|Standard receiving slit box # 1"
*HW_R_OPT_NAME-1 "標準受光光学ユニット1|Standard receiving unit # 1"
*HW_R_OPT_NAME-2 "標準受光光学ユニット2|Standard receiving optical unit # 2"
*HW_R_OPT_NAME-3 "標準受光スリットボックス2|Standard receiving slit box # 2"
*HW_R_OPT_NAME-4 "標準アッテネータ|Standard Attenuator"
*HW_R_OPT_NAME-5 "Cu Kβ|Cu K-beta"
*HW_R_OPT_NAME-6 "調整用受光スリット|Alignment receiving slit"
*HW_SAMPLE_HOLDER_ID "SMP0023"
*HW_SAMPLE_HOLDER_NAME "標準Zステージ|Standard Z stage"
*HW_XG_CURRENT_MAX "50"
*HW_XG_CURRENT_MIN "2"
*HW_XG_CURRENT_RESOLUTION "2"
*HW_XG_CURRENT_UNIT "mA"
*HW_XG_FOCUS "1mm x 10mm"
*HW_XG_FOCUS_TYPE "Normal"
*HW_XG_ID ""
*HW_XG_NAME "3kW 封入管(ID:1200)|3kW Sealed tube(ID:1200)"
*HW_XG_TARGET_ATOMIC_NUMBER "29.0000000000"
*HW_XG_TARGET_NAME "Cu"
*HW_XG_TYPE "Hermetic"
*HW_XG_VOLTAGE_MAX "60"
*HW_XG_VOLTAGE_MIN "20"
*HW_XG_VOLTAGE_RESOLUTION "2"
*HW_XG_VOLTAGE_UNIT "kV"
*HW_XG_WATT_MAX "2"
*HW_XG_WATT_UNIT "kW"
*HW_XG_WAVE_LENGTH_ALPHA1 "1.540593"
*HW_XG_WAVE_LENGTH_ALPHA2 "1.544414"
*HW_XG_WAVE_LENGTH_BETA "1.392250"
*MEAS_COND_AXIS_NAME-0 "2θ/θ"
*MEAS_COND_AXIS_NAME-1 "2θ"
*MEAS_COND_AXIS_NAME-2 "ω"
*MEAS_COND_AXIS_NAME-3 "Z"
*MEAS_COND_AXIS_NAME-4 "2θ/ω"
*MEAS_COND_AXIS_NAME-5 "θs"
*MEAS_COND_AXIS_NAME-6 "θd"
*MEAS_COND_AXIS_NAME-7 "Ts"
*MEAS_COND_AXIS_NAME-8 "CBO選択スリット"
*MEAS_COND_AXIS_NAME-9 "M"
*MEAS_COND_AXIS_NAME-10 "入射平行スリット"
*MEAS_COND_AXIS_NAME-11 "入射スリット"
*MEAS_COND_AXIS_NAME-12 ""
*MEAS_COND_AXIS_NAME-13 "Zs"
*MEAS_COND_AXIS_NAME-14 "入射光学素子"
*MEAS_COND_AXIS_NAME-15 "長手制限スリット"
*MEAS_COND_AXIS_NAME-16 "センタースリット"
*MEAS_COND_AXIS_NAME-17 "フィルター"
*MEAS_COND_AXIS_NAME-18 "受光スリット1"
*MEAS_COND_AXIS_NAME-19 "受光スリット2"
*MEAS_COND_AXIS_NAME-20 "受光光学素子"
*MEAS_COND_AXIS_NAME-21 "受光平行スリット"
*MEAS_COND_AXIS_NAME-22 "調整用受光スリット"
*MEAS_COND_AXIS_NAME-23 ""
*MEAS_COND_AXIS_NAME-24 ""
*MEAS_COND_AXIS_NAME-25 "Zd"
*MEAS_COND_AXIS_NAME-26 "アッテネータ"
*MEAS_COND_AXIS_NAME-27 "検出器モノクロメータ"
*MEAS_COND_AXIS_NAME-28 "モノクロメータスリット"
*MEAS_COND_AXIS_NAME-29 "プライマリビーム"
*MEAS_COND_AXIS_NAME-30 "PHA"
*MEAS_COND_AXIS_NAME_INTERNAL-0 "TwoThetaTheta"
*MEAS_COND_AXIS_NAME_INTERNAL-1 "TwoTheta"
*MEAS_COND_AXIS_NAME_INTERNAL-2 "Omega"
*MEAS_COND_AXIS_NAME_INTERNAL-3 "Z"
*MEAS_COND_AXIS_NAME_INTERNAL-4 "TwoThetaOmega"
*MEAS_COND_AXIS_NAME_INTERNAL-5 "ThetaS"
*MEAS_COND_AXIS_NAME_INTERNAL-6 "ThetaD"
*MEAS_COND_AXIS_NAME_INTERNAL-7 "Ts"
*MEAS_COND_AXIS_NAME_INTERNAL-8 "CBO"
*MEAS_COND_AXIS_NAME_INTERNAL-9 "CBO-M"
*MEAS_COND_AXIS_NAME_INTERNAL-10 "IncidentSollerSlit"
*MEAS_COND_AXIS_NAME_INTERNAL-11 "IncidentSlitBox"
*MEAS_COND_AXIS_NAME_INTERNAL-12 "IncidentSlitBox-_Axis"
*MEAS_COND_AXIS_NAME_INTERNAL-13 "Zs"
*MEAS_COND_AXIS_NAME_INTERNAL-14 "IncidentMonochromator"
*MEAS_COND_AXIS_NAME_INTERNAL-15 "IncidentAxdSlit"
*MEAS_COND_AXIS_NAME_INTERNAL-16 "CenterSlit"
*MEAS_COND_AXIS_NAME_INTERNAL-17 "Filter"
*MEAS_COND_AXIS_NAME_INTERNAL-18 "ReceivingSlitBox1"
*MEAS_COND_AXIS_NAME_INTERNAL-19 "ReceivingSlitBox2"
*MEAS_COND_AXIS_NAME_INTERNAL-20 "ReceivingOptics"
*MEAS_COND_AXIS_NAME_INTERNAL-21 "ReceivingSollerSlit"
*MEAS_COND_AXIS_NAME_INTERNAL-22 "ReceivingAxdSlit"
*MEAS_COND_AXIS_NAME_INTERNAL-23 "ReceivingSlitBox1-_Axis"
*MEAS_COND_AXIS_NAME_INTERNAL-24 "ReceivingSlitBox2-_Axis"
*MEAS_COND_AXIS_NAME_INTERNAL-25 "ReceivingSlitBox2-Zd"
*MEAS_COND_AXIS_NAME_INTERNAL-26 "Attenuator"
*MEAS_COND_AXIS_NAME_INTERNAL-27 "CounterMonochromator"
*MEAS_COND_AXIS_NAME_INTERNAL-28 "CounterSlit"
*MEAS_COND_AXIS_NAME_INTERNAL-29 "IncidentPrimary"
*MEAS_COND_AXIS_NAME_INTERNAL-30 "PHA"
*MEAS_COND_AXIS_NAME_MAGICNO-0 "83951616.0000000000"
*MEAS_COND_AXIS_NAME_MAGICNO-1 "268632064.0000000000"
*MEAS_COND_AXIS_NAME_MAGICNO-2 "268500992.0000000000"
*MEAS_COND_AXIS_NAME_MAGICNO-3 "285278208.0000000000"
*MEAS_COND_AXIS_NAME_MAGICNO-4 "83951616.0000000000"
*MEAS_COND_AXIS_NAME_MAGICNO-5 "131072.0000000000"
*MEAS_COND_AXIS_NAME_MAGICNO-6 "131072.0000000000"
*MEAS_COND_AXIS_NAME_MAGICNO-7 "318898176.0000000000"
*MEAS_COND_AXIS_NAME_MAGICNO-8 "20971521.0000000000"
*MEAS_COND_AXIS_NAME_MAGICNO-9 "285343744.0000000000"
*MEAS_COND_AXIS_NAME_MAGICNO-10 "20971521.0000000000"
*MEAS_COND_AXIS_NAME_MAGICNO-11 "22020097.0000000000"
*MEAS_COND_AXIS_NAME_MAGICNO-12 "25165824.0000000000"
*MEAS_COND_AXIS_NAME_MAGICNO-13 "318898176.0000000000"
*MEAS_COND_AXIS_NAME_MAGICNO-14 "1.0000000000"
*MEAS_COND_AXIS_NAME_MAGICNO-15 "20971521.0000000000"
*MEAS_COND_AXIS_NAME_MAGICNO-16 "20971521.0000000000"
*MEAS_COND_AXIS_NAME_MAGICNO-17 "20971521.0000000000"
*MEAS_COND_AXIS_NAME_MAGICNO-18 "23068673.0000000000"
*MEAS_COND_AXIS_NAME_MAGICNO-19 "23068673.0000000000"
*MEAS_COND_AXIS_NAME_MAGICNO-20 "20971521.0000000000"
*MEAS_COND_AXIS_NAME_MAGICNO-21 "20971521.0000000000"
*MEAS_COND_AXIS_NAME_MAGICNO-22 "20971521.0000000000"
*MEAS_COND_AXIS_NAME_MAGICNO-23 "25165824.0000000000"
*MEAS_COND_AXIS_NAME_MAGICNO-24 "25165824.0000000000"
*MEAS_COND_AXIS_NAME_MAGICNO-25 "285343744.0000000000"
*MEAS_COND_AXIS_NAME_MAGICNO-26 "17301505.0000000000"
*MEAS_COND_AXIS_NAME_MAGICNO-27 "20971521.0000000000"
*MEAS_COND_AXIS_NAME_MAGICNO-28 "20971521.0000000000"
*MEAS_COND_AXIS_NAME_MAGICNO-29 "20971521.0000000000"
*MEAS_COND_AXIS_NAME_MAGICNO-30 "0.0000000000"
*MEAS_COND_AXIS_OFFSET-0 "-"
*MEAS_COND_AXIS_OFFSET-1 "0.1501000000"
*MEAS_COND_AXIS_OFFSET-2 "0.3849000000"
*MEAS_COND_AXIS_OFFSET-3 "-"
*MEAS_COND_AXIS_OFFSET-4 "-"
*MEAS_COND_AXIS_OFFSET-5 "0.3849000000"
*MEAS_COND_AXIS_OFFSET-6 "-0.2348000000"
*MEAS_COND_AXIS_OFFSET-7 "-"
*MEAS_COND_AXIS_OFFSET-8 "-"
*MEAS_COND_AXIS_OFFSET-9 "-"
*MEAS_COND_AXIS_OFFSET-10 "-"
*MEAS_COND_AXIS_OFFSET-11 "-"
*MEAS_COND_AXIS_OFFSET-12 "-"
*MEAS_COND_AXIS_OFFSET-13 "-"
*MEAS_COND_AXIS_OFFSET-14 "-"
*MEAS_COND_AXIS_OFFSET-15 "-"
*MEAS_COND_AXIS_OFFSET-16 "-"
*MEAS_COND_AXIS_OFFSET-17 "-"
*MEAS_COND_AXIS_OFFSET-18 "-"
*MEAS_COND_AXIS_OFFSET-19 "-"
*MEAS_COND_AXIS_OFFSET-20 "-"
*MEAS_COND_AXIS_OFFSET-21 "-"
*MEAS_COND_AXIS_OFFSET-22 "-"
*MEAS_COND_AXIS_OFFSET-23 "-"
*MEAS_COND_AXIS_OFFSET-24 "-"
*MEAS_COND_AXIS_OFFSET-25 "-"
*MEAS_COND_AXIS_OFFSET-26 "-"
*MEAS_COND_AXIS_OFFSET-27 "-"
*MEAS_COND_AXIS_OFFSET-28 "-"
*MEAS_COND_AXIS_OFFSET-29 "-"
*MEAS_COND_AXIS_OFFSET-30 "-"
*MEAS_COND_AXIS_POSITION-0 "0.0000000000"
*MEAS_COND_AXIS_POSITION-1 "0.0000000000"
*MEAS_COND_AXIS_POSITION-2 "0.0000000000"
*MEAS_COND_AXIS_POSITION-3 "-0.1000000000"
*MEAS_COND_AXIS_POSITION-4 "0.0000000000"
*MEAS_COND_AXIS_POSITION-5 "0.0000000000"
*MEAS_COND_AXIS_POSITION-6 "0.0000000000"
*MEAS_COND_AXIS_POSITION-7 "0.0000000000"
*MEAS_COND_AXIS_POSITION-8 "BB"
*MEAS_COND_AXIS_POSITION-9 "0.0000000000"
*MEAS_COND_AXIS_POSITION-10 "Soller_slit_5.0deg"
*MEAS_COND_AXIS_POSITION-11 "2/3deg"
*MEAS_COND_AXIS_POSITION-12 "2.2088000000"
*MEAS_COND_AXIS_POSITION-13 "0.3631200000"
*MEAS_COND_AXIS_POSITION-14 "0.0000000000"
*MEAS_COND_AXIS_POSITION-15 "5.0mm"
*MEAS_COND_AXIS_POSITION-16 "None"
*MEAS_COND_AXIS_POSITION-17 "Cu_K-beta"
*MEAS_COND_AXIS_POSITION-18 "20.000mm"
*MEAS_COND_AXIS_POSITION-19 "20.000mm"
*MEAS_COND_AXIS_POSITION-20 "No_unit"
*MEAS_COND_AXIS_POSITION-21 "Soller_slit_5.0deg"
*MEAS_COND_AXIS_POSITION-22 "None"
*MEAS_COND_AXIS_POSITION-23 "20.0000000000"
*MEAS_COND_AXIS_POSITION-24 "20.0000000000"
*MEAS_COND_AXIS_POSITION-25 "0.1690600000"
*MEAS_COND_AXIS_POSITION-26 "Open"
*MEAS_COND_AXIS_POSITION-27 "None"
*MEAS_COND_AXIS_POSITION-28 "None"
*MEAS_COND_AXIS_POSITION-29 "None"
*MEAS_COND_AXIS_POSITION-30 "44.0000000000"
*MEAS_COND_AXIS_UNIT-0 "deg"
*MEAS_COND_AXIS_UNIT-1 "deg"
*MEAS_COND_AXIS_UNIT-2 "deg"
*MEAS_COND_AXIS_UNIT-3 "mm"
*MEAS_COND_AXIS_UNIT-4 "deg"
*MEAS_COND_AXIS_UNIT-5 "deg"
*MEAS_COND_AXIS_UNIT-6 "deg"
*MEAS_COND_AXIS_UNIT-7 "mm"
*MEAS_COND_AXIS_UNIT-8 ""
*MEAS_COND_AXIS_UNIT-9 "pulse"
*MEAS_COND_AXIS_UNIT-10 ""
*MEAS_COND_AXIS_UNIT-11 ""
*MEAS_COND_AXIS_UNIT-12 "mm"
*MEAS_COND_AXIS_UNIT-13 "mm"
*MEAS_COND_AXIS_UNIT-14 ""
*MEAS_COND_AXIS_UNIT-15 ""
*MEAS_COND_AXIS_UNIT-16 ""
*MEAS_COND_AXIS_UNIT-17 ""
*MEAS_COND_AXIS_UNIT-18 ""
*MEAS_COND_AXIS_UNIT-19 ""
*MEAS_COND_AXIS_UNIT-20 ""
*MEAS_COND_AXIS_UNIT-21 ""
*MEAS_COND_AXIS_UNIT-22 ""
*MEAS_COND_AXIS_UNIT-23 "mm"
*MEAS_COND_AXIS_UNIT-24 "mm"
*MEAS_COND_AXIS_UNIT-25 "mm"
*MEAS_COND_AXIS_UNIT-26 ""
*MEAS_COND_AXIS_UNIT-27 ""
*MEAS_COND_AXIS_UNIT-28 ""
*MEAS_COND_AXIS_UNIT-29 ""
*MEAS_COND_AXIS_UNIT-30 "div"
*MEAS_COND_COUNTER_CNTLOSS_CORR "0.0000000000"
*MEAS_COND_COUNTER_PHABASE "44.0000000000"
*MEAS_COND_COUNTER_PHAWINDOW "9.0000000000"
*MEAS_COND_COUNTER_PHA_UNIT "div"
*MEAS_COND_COUNTER_TAUDIFF "0.0000000000"
*MEAS_COND_COUNTER_TAUINT "0.0000000000"
*MEAS_COND_IRRADIATION_MODE "OFF"
*MEAS_COND_IRRADIATION_WIDTH ""
*MEAS_COND_OPT_ATTR "集中法"
*MEAS_COND_OPT_NAME "@集中法"
*MEAS_COND_UNSYMMETRIC_MODE "OFF"
*MEAS_COND_XG_CURRENT "30.0000000000"
*MEAS_COND_XG_VOLTAGE "40.0000000000"
*MEAS_COND_XG_WAVE_TYPE "Ka"
*MEAS_DATA_COUNT "4250.0000000000"
*MEAS_SCAN_AXIS_X "2θ/θ"
*MEAS_SCAN_AXIS_X_INTERNAL "TwoThetaTheta"
*MEAS_SCAN_END_TIME "04/22/21 13:30:54"
*MEAS_SCAN_MODE "CONTINUOUS"
*MEAS_SCAN_MONITOR "0"
*MEAS_SCAN_RESOLUTION_X "0.0002"
*MEAS_SCAN_SPEED "20.0"
*MEAS_SCAN_SPEED_UNIT "deg/min"
*MEAS_SCAN_START "5.0000000000"
*MEAS_SCAN_START_TIME "04/22/21 13:26:04"
*MEAS_SCAN_STEP "0.0200000000"
*MEAS_SCAN_STOP "90.0000000000"
*MEAS_SCAN_UNIT_X "deg"
*MEAS_SCAN_UNIT_Y "counts"
*RAS_HEADER_END
*RAS_INT_START
5.0000 162.0000 1.0000
5.0600 176.0000 1.0000
5.1200 188.0000 1.0000
5.1800 182.0000 1.0000
5.2400 158.0000 1.0000
5.3000 167.0000 1.0000
5.3600 184.0000 1.0000
5.4200 175.0000 1.0000
5.4800 189.0000 1.0000
5.5400 177.0000 1.0000
5.6000 187.0000 1.0000
5.6600 196.0000 1.0000
5.7200 170.0000 1.0000
5.7800 201.0000 1.0000
5.8400 193.0000 1.0000
5.9000 179.0000 1.0000
5.9600 192.0000 1.0000
6.0200 158.0000 1.0000
6.0800 182.0000 1.0000
6.1400 169.0000 1.0000
6.2000 142.0000 1.0000
6.2600 184.0000 1.0000
6.3200 200.0000 1.0000
6.3800 203.0000 1.0000
6.4400 187.0000 1.0000
6.5000 215.0000 1.0000
6.5600 202.0000 1.0000
6.6200 195.0000 1.0000
6.6800 178.0000 1.0000
6.7400 210.0000 1.0000
6.8000 175.0000 1.0000
6.8600 148.0000 1.0000
6.9200 175.0000 1.0000
6.9800 201.0000 1.0000
7.0400 191.0000 1.0000
7.1000 174.0000 1.0000
7.1600 189.0000 1.0000
7.2200 184.0000 1.0000
7.2800 164.0000 1.0000
7.3400 195.0000 1.0000
7.4000 185.0000 1.0000
7.4600 198.0000 1.0000
7.5200 175.0000 1.0000
7.5800 167.0000 1.0000
7.6400 166.0000 1.0000
7.7000 172.0000 1.0000
7.7600 189.0000 1.0000
7.8200 170.0000 1.0000
7.8800 158.0000 1.0000
7.9400 182.0000 1.0000
8.0000 191.0000 1.0000
8.0600 173.0000 1.0000
8.1200 147.0000 1.0000
8.1800 170.0000 1.0000
8.2400 160.0000 1.0000
8.3000 174.0000 1.0000
8.3600 182.0000 1.0000
8.4200 168.0000 1.0000
8.4800 159.0000 1.0000
8.5400 152.0000 1.0000
8.6000 166.0000 1.0000
8.6600 165.0000 1.0000
8.7200 171.0000 1.0000
8.7800 188.0000 1.0000
8.8400 147.0000 1.0000
8.9000 186.0000 1.0000
8.9600 151.0000 1.0000
9.0200 170.0000 1.0000
9.0800 191.0000 1.0000
9.1400 146.0000 1.0000
9.2000 171.0000 1.0000
9.2600 166.0000 1.0000
9.3200 154.0000 1.0000
9.3800 163.0000 1.0000
9.4400 183.0000 1.0000
9.5000 140.0000 1.0000
9.5600 152.0000 1.0000
9.6200 169.0000 1.0000
9.6800 152.0000 1.0000
9.7400 171.0000 1.0000
9.8000 148.0000 1.0000
9.8600 139.0000 1.0000
9.9200 154.0000 1.0000
9.9800 163.0000 1.0000
10.0400 141.0000 1.0000
10.1000 160.0000 1.0000
10.1600 151.0000 1.0000
10.2200 168.0000 1.0000
10.2800 153.0000 1.0000
10.3400 148.0000 1.0000
10.4000 177.0000 1.0000
10.4600 135.0000 1.0000
10.5200 149.0000 1.0000
10.5800 132.0000 1.0000
10.6400 164.0000 1.0000
10.7000 171.0000 1.0000
10.7600 157.0000 1.0000
10.8200 158.0000 1.0000
10.8800 158.0000 1.0000
10.9400 158.0000 1.0000
11.0000 156.0000 1.0000
11.0600 150.0000 1.0000
11.1200 162.0000 1.0000
11.1800 155.0000 1.0000
11.2400 133.0000 1.0000
11.3000 153.0000 1.0000
11.3600 150.0000 1.0000
11.4200 152.0000 1.0000
11.4800 154.0000 1.0000
11.5400 158.0000 1.0000
11.6000 147.0000 1.0000
11.6600 158.0000 1.0000
11.7200 138.0000 1.0000
11.7800 152.0000 1.0000
11.8400 126.0000 1.0000
11.9000 147.0000 1.0000
11.9600 127.0000 1.0000
12.0200 123.0000 1.0000
12.0800 134.0000 1.0000
12.1400 142.0000 1.0000
12.2000 138.0000 1.0000
12.2600 141.0000 1.0000
12.3200 136.0000 1.0000
12.3800 150.0000 1.0000
12.4400 152.0000 1.0000
12.5000 142.0000 1.0000
12.5600 145.0000 1.0000
12.6200 149.0000 1.0000
12.6800 149.0000 1.0000
12.7400 134.0000 1.0000
12.8000 133.0000 1.0000
12.8600 126.0000 1.0000
12.9200 128.0000 1.0000
12.9800 121.0000 1.0000
13.0400 141.0000 1.0000
13.1000 126.0000 1.0000
13.1600 132.0000 1.0000
13.2200 141.0000 1.0000
13.2800 143.0000 1.0000
13.3400 121.0000 1.0000
13.4000 125.0000 1.0000
13.4600 111.0000 1.0000
13.5200 118.0000 1.0000
13.5800 129.0000 1.0000
13.6400 143.0000 1.0000
13.7000 135.0000 1.0000
13.7600 127.0000 1.0000
13.8200 125.0000 1.0000
13.8800 120.0000 1.0000
13.9400 140.0000 1.0000
14.0000 126.0000 1.0000
14.0600 138.0000 1.0000
14.1200 120.0000 1.0000
14.1800 139.0000 1.0000
14.2400 125.0000 1.0000
14.3000 137.0000 1.0000
14.3600 104.0000 1.0000
14.4200 118.0000 1.0000
14.4800 128.0000 1.0000
14.5400 115.0000 1.0000
14.6000 143.0000 1.0000
14.6600 105.0000 1.0000
14.7200 117.0000 1.0000
14.7800 130.0000 1.0000
14.8400 131.0000 1.0000
14.9000 112.0000 1.0000
14.9600 110.0000 1.0000
15.0200 110.0000 1.0000
15.0800 108.0000 1.0000
15.1400 123.0000 1.0000
15.2000 115.0000 1.0000
15.2600 116.0000 1.0000
15.3200 117.0000 1.0000
15.3800 117.0000 1.0000
15.4400 116.0000 1.0000
15.5000 108.0000 1.0000
15.5600 102.0000 1.0000
15.6200 108.0000 1.0000
15.6800 111.0000 1.0000
15.7400 119.0000 1.0000
15.8000 91.0000 1.0000
15.8600 125.0000 1.0000
15.9200 125.0000 1.0000
15.9800 102.0000 1.0000
16.0400 101.0000 1.0000
16.1000 119.0000 1.0000
16.1600 89.0000 1.0000
16.2200 89.0000 1.0000
16.2800 107.0000 1.0000
16.3400 104.0000 1.0000
16.4000 119.0000 1.0000
16.4600 93.0000 1.0000
16.5200 109.0000 1.0000
16.5800 98.0000 1.0000
16.6400 99.0000 1.0000
16.7000 100.0000 1.0000
16.7600 110.0000 1.0000
16.8200 103.0000 1.0000
16.8800 104.0000 1.0000
16.9400 94.0000 1.0000
17.0000 97.0000 1.0000
17.0600 93.0000 1.0000
17.1200 89.0000 1.0000
17.1800 78.0000 1.0000
17.2400 81.0000 1.0000
17.3000 97.0000 1.0000
17.3600 98.0000 1.0000
17.4200 87.0000 1.0000
17.4800 97.0000 1.0000
17.5400 91.0000 1.0000
17.6000 83.0000 1.0000
17.6600 92.0000 1.0000
17.7200 106.0000 1.0000
17.7800 96.0000 1.0000
17.8400 87.0000 1.0000
17.9000 80.0000 1.0000
17.9600 83.0000 1.0000
18.0200 79.0000 1.0000
18.0800 97.0000 1.0000
18.1400 101.0000 1.0000
18.2000 78.0000 1.0000
18.2600 100.0000 1.0000
18.3200 89.0000 1.0000
18.3800 80.0000 1.0000
18.4400 64.0000 1.0000
18.5000 76.0000 1.0000
18.5600 79.0000 1.0000
18.6200 87.0000 1.0000
18.6800 76.0000 1.0000
18.7400 72.0000 1.0000
18.8000 79.0000 1.0000
18.8600 87.0000 1.0000
18.9200 81.0000 1.0000
18.9800 89.0000 1.0000
19.0400 85.0000 1.0000
19.1000 91.0000 1.0000
19.1600 70.0000 1.0000
19.2200 82.0000 1.0000
19.2800 66.0000 1.0000
19.3400 75.0000 1.0000
19.4000 84.0000 1.0000
19.4600 78.0000 1.0000
19.5200 57.0000 1.0000
19.5800 66.0000 1.0000
19.6400 82.0000 1.0000
19.7000 78.0000 1.0000
19.7600 74.0000 1.0000
19.8200 69.0000 1.0000
19.8800 69.0000 1.0000
19.9400 82.0000 1.0000
20.0000 62.0000 1.0000
20.0600 66.0000 1.0000
20.1200 84.0000 1.0000
20.1800 56.0000 1.0000
20.2400 64.0000 1.0000
20.3000 78.0000 1.0000
20.3600 83.0000 1.0000
20.4200 84.0000 1.0000
20.4800 74.0000 1.0000
20.5400 57.0000 1.0000
20.6000 68.0000 1.0000
20.6600 63.0000 1.0000
20.7200 75.0000 1.0000
20.7800 89.0000 1.0000
20.8400 60.0000 1.0000
20.9000 67.0000 1.0000
20.9600 64.0000 1.0000
21.0200 71.0000 1.0000
21.0800 75.0000 1.0000
21.1400 75.0000 1.0000
21.2000 76.0000 1.0000
21.2600 71.0000 1.0000
21.3200 69.0000 1.0000
21.3800 50.0000 1.0000
21.4400 67.0000 1.0000
21.5000 63.0000 1.0000
21.5600 68.0000 1.0000
21.6200 59.0000 1.0000
21.6800 80.0000 1.0000
21.7400 53.0000 1.0000
21.8000 58.0000 1.0000
21.8600 58.0000 1.0000
21.9200 66.0000 1.0000
21.9800 50.0000 1.0000
22.0400 63.0000 1.0000
22.1000 73.0000 1.0000
22.1600 66.0000 1.0000
22.2200 53.0000 1.0000
22.2800 51.0000 1.0000
22.3400 48.0000 1.0000
22.4000 57.0000 1.0000
22.4600 50.0000 1.0000
22.5200 51.0000 1.0000
22.5800 52.0000 1.0000
22.6400 72.0000 1.0000
22.7000 66.0000 1.0000
22.7600 48.0000 1.0000
22.8200 61.0000 1.0000
22.8800 58.0000 1.0000
22.9400 54.0000 1.0000
23.0000 62.0000 1.0000
23.0600 55.0000 1.0000
23.1200 48.0000 1.0000
23.1800 39.0000 1.0000
23.2400 65.0000 1.0000
23.3000 53.0000 1.0000
23.3600 61.0000 1.0000
23.4200 71.0000 1.0000
23.4800 50.0000 1.0000
23.5400 60.0000 1.0000
23.6000 58.0000 1.0000
23.6600 54.0000 1.0000
23.7200 63.0000 1.0000
23.7800 64.0000 1.0000
23.8400 47.0000 1.0000
23.9000 72.0000 1.0000
23.9600 55.0000 1.0000
24.0200 62.0000 1.0000
24.0800 58.0000 1.0000
24.1400 57.0000 1.0000
24.2000 66.0000 1.0000
24.2600 55.0000 1.0000
24.3200 63.0000 1.0000
24.3800 53.0000 1.0000
24.4400 45.0000 1.0000
24.5000 57.0000 1.0000
24.5600 48.0000 1.0000
24.6200 51.0000 1.0000
24.6800 59.0000 1.0000
24.7400 55.0000 1.0000
24.8000 48.0000 1.0000
24.8600 55.0000 1.0000
24.9200 42.0000 1.0000
24.9800 57.0000 1.0000
25.0400 49.0000 1.0000
25.1000 56.0000 1.0000
25.1600 41.0000 1.0000
25.2200 46.0000 1.0000
25.2800 59.0000 1.0000
25.3400 47.0000 1.0000
25.4000 46.0000 1.0000
25.4600 53.0000 1.0000
25.5200 84.0000 1.0000
25.5800 117.0000 1.0000
25.6400 88.0000 1.0000
25.7000 74.0000 1.0000
25.7600 54.0000 1.0000
25.8200 60.0000 1.0000
25.8800 60.0000 1.0000
25.9400 42.0000 1.0000
26.0000 52.0000 1.0000
26.0600 49.0000 1.0000
26.1200 57.0000 1.0000
26.1800 62.0000 1.0000
26.2400 50.0000 1.0000
26.3000 63.0000 1.0000
26.3600 56.0000 1.0000
26.4200 69.0000 1.0000
26.4800 71.0000 1.0000
26.5400 60.0000 1.0000
26.6000 79.0000 1.0000
26.6600 118.0000 1.0000
26.7200 280.0000 1.0000
26.7800 1098.0000 1.0000
26.8400 600.0000 1.0000
26.9000 162.0000 1.0000
26.9600 70.0000 1.0000
27.0200 61.0000 1.0000
27.0800 41.0000 1.0000
27.1400 47.0000 1.0000
27.2000 59.0000 1.0000
27.2600 42.0000 1.0000
27.3200 53.0000 1.0000
27.3800 37.0000 1.0000
27.4400 45.0000 1.0000
27.5000 49.0000 1.0000
27.5600 50.0000 1.0000
27.6200 40.0000 1.0000
27.6800 61.0000 1.0000
27.7400 52.0000 1.0000
27.8000 39.0000 1.0000
27.8600 62.0000 1.0000
27.9200 57.0000 1.0000
27.9800 41.0000 1.0000
28.0400 50.0000 1.0000
28.1000 61.0000 1.0000
28.1600 49.0000 1.0000
28.2200 46.0000 1.0000
28.2800 53.0000 1.0000
28.3400 44.0000 1.0000
28.4000 54.0000 1.0000
28.4600 50.0000 1.0000
28.5200 53.0000 1.0000
28.5800 45.0000 1.0000
28.6400 44.0000 1.0000
28.7000 48.0000 1.0000
28.7600 43.0000 1.0000
28.8200 60.0000 1.0000
28.8800 32.0000 1.0000
28.9400 51.0000 1.0000
29.0000 42.0000 1.0000
29.0600 32.0000 1.0000
29.1200 39.0000 1.0000
29.1800 44.0000 1.0000
29.2400 42.0000 1.0000
29.3000 40.0000 1.0000
29.3600 42.0000 1.0000
29.4200 40.0000 1.0000
29.4800 41.0000 1.0000
29.5400 34.0000 1.0000
29.6000 38.0000 1.0000
29.6600 45.0000 1.0000
29.7200 50.0000 1.0000
29.7800 39.0000 1.0000
29.8400 48.0000 1.0000
29.9000 35.0000 1.0000
29.9600 39.0000 1.0000
30.0200 36.0000 1.0000
30.0800 56.0000 1.0000
30.1400 55.0000 1.0000
30.2000 45.0000 1.0000
30.2600 37.0000 1.0000
30.3200 49.0000 1.0000
30.3800 39.0000 1.0000
30.4400 38.0000 1.0000
30.5000 37.0000 1.0000
30.5600 45.0000 1.0000
30.6200 51.0000 1.0000
30.6800 41.0000 1.0000
30.7400 37.0000 1.0000
30.8000 37.0000 1.0000
30.8600 34.0000 1.0000
30.9200 49.0000 1.0000
30.9800 38.0000 1.0000
31.0400 42.0000 1.0000
31.1000 50.0000 1.0000
31.1600 29.0000 1.0000
31.2200 50.0000 1.0000
31.2800 43.0000 1.0000
31.3400 42.0000 1.0000
31.4000 43.0000 1.0000
31.4600 28.0000 1.0000
31.5200 53.0000 1.0000
31.5800 50.0000 1.0000
31.6400 40.0000 1.0000
31.7000 41.0000 1.0000
31.7600 24.0000 1.0000
31.8200 53.0000 1.0000
31.8800 40.0000 1.0000
31.9400 45.0000 1.0000
32.0000 44.0000 1.0000
32.0600 26.0000 1.0000
32.1200 45.0000 1.0000
32.1800 51.0000 1.0000
32.2400 55.0000 1.0000
32.3000 160.0000 1.0000
32.3600 97.0000 1.0000
32.4200 80.0000 1.0000
32.4800 49.0000 1.0000
32.5400 60.0000 1.0000
32.6000 37.0000 1.0000
32.6600 43.0000 1.0000
32.7200 56.0000 1.0000
32.7800 77.0000 1.0000
32.8400 80.0000 1.0000
32.9000 277.0000 1.0000
32.9600 611.0000 1.0000
33.0200 365.0000 1.0000
33.0800 100.0000 1.0000
33.1400 57.0000 1.0000
33.2000 54.0000 1.0000
33.2600 51.0000 1.0000
33.3200 63.0000 1.0000
33.3800 73.0000 1.0000
33.4400 78.0000 1.0000
33.5000 48.0000 1.0000
33.5600 45.0000 1.0000
33.6200 44.0000 1.0000
33.6800 34.0000 1.0000
33.7400 40.0000 1.0000
33.8000 46.0000 1.0000
33.8600 47.0000 1.0000
33.9200 39.0000 1.0000
33.9800 37.0000 1.0000
34.0400 46.0000 1.0000
34.1000 46.0000 1.0000
34.1600 45.0000 1.0000
34.2200 41.0000 1.0000
34.2800 40.0000 1.0000
34.3400 45.0000 1.0000
34.4000 38.0000 1.0000
34.4600 49.0000 1.0000
34.5200 40.0000 1.0000
34.5800 38.0000 1.0000
34.6400 45.0000 1.0000
34.7000 38.0000 1.0000
34.7600 30.0000 1.0000
34.8200 38.0000 1.0000
34.8800 35.0000 1.0000
34.9400 34.0000 1.0000
35.0000 33.0000 1.0000
35.0600 42.0000 1.0000
35.1200 38.0000 1.0000
35.1800 39.0000 1.0000
35.2400 46.0000 1.0000
35.3000 45.0000 1.0000
35.3600 39.0000 1.0000
35.4200 46.0000 1.0000
35.4800 48.0000 1.0000
35.5400 51.0000 1.0000
35.6000 26.0000 1.0000
35.6600 34.0000 1.0000
35.7200 43.0000 1.0000
35.7800 32.0000 1.0000
35.8400 30.0000 1.0000
35.9000 36.0000 1.0000
35.9600 41.0000 1.0000
36.0200 32.0000 1.0000
36.0800 40.0000 1.0000
36.1400 40.0000 1.0000
36.2000 54.0000 1.0000
36.2600 39.0000 1.0000
36.3200 49.0000 1.0000
36.3800 29.0000 1.0000
36.4400 36.0000 1.0000
36.5000 39.0000 1.0000
36.5600 30.0000 1.0000
36.6200 43.0000 1.0000
36.6800 32.0000 1.0000
36.7400 44.0000 1.0000
36.8000 44.0000 1.0000
36.8600 41.0000 1.0000
36.9200 45.0000 1.0000
36.9800 29.0000 1.0000
37.0400 37.0000 1.0000
37.1000 27.0000 1.0000
37.1600 40.0000 1.0000
37.2200 41.0000 1.0000
37.2800 28.0000 1.0000
37.3400 32.0000 1.0000
37.4000 34.0000 1.0000
37.4600 38.0000 1.0000
37.5200 42.0000 1.0000
37.5800 32.0000 1.0000
37.6400 70.0000 1.0000
37.7000 45.0000 1.0000
37.7600 44.0000 1.0000
37.8200 41.0000 1.0000
37.8800 37.0000 1.0000
37.9400 34.0000 1.0000
38.0000 42.0000 1.0000
38.0600 35.0000 1.0000
38.1200 50.0000 1.0000
38.1800 53.0000 1.0000
38.2400 91.0000 1.0000
38.3000 67.0000 1.0000
38.3600 53.0000 1.0000
38.4200 48.0000 1.0000
38.4800 43.0000 1.0000
38.5400 46.0000 1.0000
38.6000 63.0000 1.0000
38.6600 50.0000 1.0000
38.7200 34.0000 1.0000
38.7800 43.0000 1.0000
38.8400 45.0000 1.0000
38.9000 35.0000 1.0000
38.9600 29.0000 1.0000
39.0200 38.0000 1.0000
39.0800 34.0000 1.0000
39.1400 38.0000 1.0000
39.2000 36.0000 1.0000
39.2600 26.0000 1.0000
39.3200 35.0000 1.0000
39.3800 35.0000 1.0000
39.4400 37.0000 1.0000
39.5000 34.0000 1.0000
39.5600 25.0000 1.0000
39.6200 32.0000 1.0000
39.6800 37.0000 1.0000
39.7400 38.0000 1.0000
39.8000 45.0000 1.0000
39.8600 35.0000 1.0000
39.9200 46.0000 1.0000
39.9800 36.0000 1.0000
40.0400 38.0000 1.0000
40.1000 49.0000 1.0000
40.1600 31.0000 1.0000
40.2200 35.0000 1.0000
40.2800 46.0000 1.0000
40.3400 26.0000 1.0000
40.4000 55.0000 1.0000
40.4600 36.0000 1.0000
40.5200 37.0000 1.0000
40.5800 38.0000 1.0000
40.6400 56.0000 1.0000
40.7000 84.0000 1.0000
40.7600 104.0000 1.0000
40.8200 91.0000 1.0000
40.8800 48.0000 1.0000
40.9400 44.0000 1.0000
41.0000 41.0000 1.0000
41.0600 37.0000 1.0000
41.1200 31.0000 1.0000
41.1800 31.0000 1.0000
41.2400 39.0000 1.0000
41.3000 34.0000 1.0000
41.3600 46.0000 1.0000
41.4200 40.0000 1.0000
41.4800 66.0000 1.0000
41.5400 48.0000 1.0000
41.6000 69.0000 1.0000
41.6600 248.0000 1.0000
41.7200 146.0000 1.0000
41.7800 191.0000 1.0000
41.8400 102.0000 1.0000
41.9000 52.0000 1.0000
41.9600 39.0000 1.0000
42.0200 37.0000 1.0000
42.0800 37.0000 1.0000
42.1400 38.0000 1.0000
42.2000 50.0000 1.0000
42.2600 43.0000 1.0000
42.3200 32.0000 1.0000
42.3800 59.0000 1.0000
42.4400 51.0000 1.0000
42.5000 80.0000 1.0000
42.5600 59.0000 1.0000
42.6200 54.0000 1.0000
42.6800 81.0000 1.0000
42.7400 137.0000 1.0000
42.8000 203.0000 1.0000
42.8600 403.0000 1.0000
42.9200 1810.0000 1.0000
42.9800 1502.0000 1.0000
43.0400 1219.0000 1.0000
43.1000 603.0000 1.0000
43.1600 164.0000 1.0000
43.2200 87.0000 1.0000
43.2800 71.0000 1.0000
43.3400 62.0000 1.0000
43.4000 45.0000 1.0000
43.4600 34.0000 1.0000
43.5200 47.0000 1.0000
43.5800 48.0000 1.0000
43.6400 55.0000 1.0000
43.7000 43.0000 1.0000
43.7600 46.0000 1.0000
43.8200 40.0000 1.0000
43.8800 31.0000 1.0000
43.9400 40.0000 1.0000
44.0000 47.0000 1.0000
44.0600 47.0000 1.0000
44.1200 41.0000 1.0000
44.1800 40.0000 1.0000
44.2400 47.0000 1.0000
44.3000 39.0000 1.0000
44.3600 43.0000 1.0000
44.4200 49.0000 1.0000
44.4800 51.0000 1.0000
44.5400 43.0000 1.0000
44.6000 33.0000 1.0000
44.6600 33.0000 1.0000
44.7200 41.0000 1.0000
44.7800 38.0000 1.0000
44.8400 41.0000 1.0000
44.9000 30.0000 1.0000
44.9600 46.0000 1.0000
45.0200 41.0000 1.0000
45.0800 35.0000 1.0000
45.1400 38.0000 1.0000
45.2000 30.0000 1.0000
45.2600 30.0000 1.0000
45.3200 46.0000 1.0000
45.3800 47.0000 1.0000
45.4400 45.0000 1.0000
45.5000 34.0000 1.0000
45.5600 31.0000 1.0000
45.6200 44.0000 1.0000
45.6800 42.0000 1.0000
45.7400 52.0000 1.0000
45.8000 39.0000 1.0000
45.8600 37.0000 1.0000
45.9200 35.0000 1.0000
45.9800 44.0000 1.0000
46.0400 42.0000 1.0000
46.1000 47.0000 1.0000
46.1600 43.0000 1.0000
46.2200 36.0000 1.0000
46.2800 59.0000 1.0000
46.3400 102.0000 1.0000
46.4000 101.0000 1.0000
46.4600 72.0000 1.0000
46.5200 95.0000 1.0000
46.5800 50.0000 1.0000
46.6400 48.0000 1.0000
46.7000 48.0000 1.0000
46.7600 57.0000 1.0000
46.8200 53.0000 1.0000
46.8800 63.0000 1.0000
46.9400 50.0000 1.0000
47.0000 65.0000 1.0000
47.0600 97.0000 1.0000
47.1200 137.0000 1.0000
47.1800 193.0000 1.0000
47.2400 955.0000 1.0000
47.3000 1541.0000 1.0000
47.3600 528.0000 1.0000
47.4200 954.0000 1.0000
47.4800 164.0000 1.0000
47.5400 106.0000 1.0000
47.6000 52.0000 1.0000
47.6600 51.0000 1.0000
47.7200 39.0000 1.0000
47.7800 44.0000 1.0000
47.8400 33.0000 1.0000
47.9000 40.0000 1.0000
47.9600 48.0000 1.0000
48.0200 42.0000 1.0000
48.0800 48.0000 1.0000
48.1400 46.0000 1.0000
48.2000 38.0000 1.0000
48.2600 39.0000 1.0000
48.3200 39.0000 1.0000
48.3800 43.0000 1.0000
48.4400 43.0000 1.0000
48.5000 45.0000 1.0000
48.5600 41.0000 1.0000
48.6200 36.0000 1.0000
48.6800 37.0000 1.0000
48.7400 31.0000 1.0000
48.8000 51.0000 1.0000
48.8600 43.0000 1.0000
48.9200 35.0000 1.0000
48.9800 39.0000 1.0000
49.0400 37.0000 1.0000
49.1000 37.0000 1.0000
49.1600 27.0000 1.0000
49.2200 41.0000 1.0000
49.2800 37.0000 1.0000
49.3400 44.0000 1.0000
49.4000 28.0000 1.0000
49.4600 29.0000 1.0000
49.5200 31.0000 1.0000
49.5800 32.0000 1.0000
49.6400 35.0000 1.0000
49.7000 35.0000 1.0000
49.7600 40.0000 1.0000
49.8200 40.0000 1.0000
49.8800 43.0000 1.0000
49.9400 36.0000 1.0000
50.0000 30.0000 1.0000
50.0600 28.0000 1.0000
50.1200 32.0000 1.0000
50.1800 26.0000 1.0000
50.2400 44.0000 1.0000
50.3000 31.0000 1.0000
50.3600 28.0000 1.0000
50.4200 46.0000 1.0000
50.4800 37.0000 1.0000
50.5400 39.0000 1.0000
50.6000 43.0000 1.0000
50.6600 42.0000 1.0000
50.7200 34.0000 1.0000
50.7800 34.0000 1.0000
50.8400 47.0000 1.0000
50.9000 41.0000 1.0000
50.9600 36.0000 1.0000
51.0200 38.0000 1.0000
51.0800 31.0000 1.0000
51.1400 43.0000 1.0000
51.2000 27.0000 1.0000
51.2600 43.0000 1.0000
51.3200 35.0000 1.0000
51.3800 57.0000 1.0000
51.4400 33.0000 1.0000
51.5000 43.0000 1.0000
51.5600 37.0000 1.0000
51.6200 43.0000 1.0000
51.6800 47.0000 1.0000
51.7400 30.0000 1.0000
51.8000 43.0000 1.0000
51.8600 54.0000 1.0000
51.9200 38.0000 1.0000
51.9800 48.0000 1.0000
52.0400 34.0000 1.0000
52.1000 25.0000 1.0000
52.1600 45.0000 1.0000
52.2200 36.0000 1.0000
52.2800 24.0000 1.0000
52.3400 35.0000 1.0000
52.4000 36.0000 1.0000
52.4600 27.0000 1.0000
52.5200 37.0000 1.0000
52.5800 35.0000 1.0000
52.6400 36.0000 1.0000
52.7000 35.0000 1.0000
52.7600 37.0000 1.0000
52.8200 42.0000 1.0000
52.8800 33.0000 1.0000
52.9400 41.0000 1.0000
53.0000 40.0000 1.0000
53.0600 42.0000 1.0000
53.1200 37.0000 1.0000
53.1800 28.0000 1.0000
53.2400 47.0000 1.0000
53.3000 38.0000 1.0000
53.3600 40.0000 1.0000
53.4200 50.0000 1.0000
53.4800 59.0000 1.0000
53.5400 53.0000 1.0000
53.6000 71.0000 1.0000
53.6600 240.0000 1.0000
53.7200 857.0000 1.0000
53.7800 253.0000 1.0000
53.8400 377.0000 1.0000
53.9000 230.0000 1.0000
53.9600 55.0000 1.0000
54.0200 59.0000 1.0000
54.0800 36.0000 1.0000
54.1400 32.0000 1.0000
54.2000 26.0000 1.0000
54.2600 35.0000 1.0000
54.3200 40.0000 1.0000
54.3800 30.0000 1.0000
54.4400 34.0000 1.0000
54.5000 39.0000 1.0000
54.5600 45.0000 1.0000
54.6200 28.0000 1.0000
54.6800 31.0000 1.0000
54.7400 31.0000 1.0000
54.8000 32.0000 1.0000
54.8600 37.0000 1.0000
54.9200 25.0000 1.0000
54.9800 37.0000 1.0000
55.0400 39.0000 1.0000
55.1000 29.0000 1.0000
55.1600 40.0000 1.0000
55.2200 44.0000 1.0000
55.2800 43.0000 1.0000
55.3400 50.0000 1.0000
55.4000 37.0000 1.0000
55.4600 34.0000 1.0000
55.5200 34.0000 1.0000
55.5800 30.0000 1.0000
55.6400 33.0000 1.0000
55.7000 39.0000 1.0000
55.7600 39.0000 1.0000
55.8200 48.0000 1.0000
55.8800 32.0000 1.0000
55.9400 30.0000 1.0000
56.0000 26.0000 1.0000
56.0600 36.0000 1.0000
56.1200 32.0000 1.0000
56.1800 31.0000 1.0000
56.2400 30.0000 1.0000
56.3000 37.0000 1.0000
56.3600 47.0000 1.0000
56.4200 45.0000 1.0000
56.4800 40.0000 1.0000
56.5400 42.0000 1.0000
56.6000 32.0000 1.0000
56.6600 34.0000 1.0000
56.7200 40.0000 1.0000
56.7800 32.0000 1.0000
56.8400 40.0000 1.0000
56.9000 39.0000 1.0000
56.9600 49.0000 1.0000
57.0200 37.0000 1.0000
57.0800 34.0000 1.0000
57.1400 42.0000 1.0000
57.2000 41.0000 1.0000
57.2600 32.0000 1.0000
57.3200 36.0000 1.0000
57.3800 48.0000 1.0000
57.4400 29.0000 1.0000
57.5000 25.0000 1.0000
57.5600 33.0000 1.0000
57.6200 40.0000 1.0000
57.6800 38.0000 1.0000
57.7400 38.0000 1.0000
57.8000 26.0000 1.0000
57.8600 37.0000 1.0000
57.9200 36.0000 1.0000
57.9800 36.0000 1.0000
58.0400 29.0000 1.0000
58.1000 38.0000 1.0000
58.1600 38.0000 1.0000
58.2200 40.0000 1.0000
58.2800 41.0000 1.0000
58.3400 38.0000 1.0000
58.4000 37.0000 1.0000
58.4600 37.0000 1.0000
58.5200 36.0000 1.0000
58.5800 34.0000 1.0000
58.6400 43.0000 1.0000
58.7000 44.0000 1.0000
58.7600 54.0000 1.0000
58.8200 84.0000 1.0000
58.8800 53.0000 1.0000
58.9400 50.0000 1.0000
59.0000 50.0000 1.0000
59.0600 28.0000 1.0000
59.1200 38.0000 1.0000
59.1800 34.0000 1.0000
59.2400 49.0000 1.0000
59.3000 43.0000 1.0000
59.3600 34.0000 1.0000
59.4200 35.0000 1.0000
59.4800 53.0000 1.0000
59.5400 55.0000 1.0000
59.6000 41.0000 1.0000
59.6600 41.0000 1.0000
59.7200 58.0000 1.0000
59.7800 40.0000 1.0000
59.8400 35.0000 1.0000
59.9000 32.0000 1.0000
59.9600 37.0000 1.0000
60.0200 35.0000 1.0000
60.0800 45.0000 1.0000
60.1400 30.0000 1.0000
60.2000 47.0000 1.0000
60.2600 44.0000 1.0000
60.3200 30.0000 1.0000
60.3800 35.0000 1.0000
60.4400 41.0000 1.0000
60.5000 55.0000 1.0000
60.5600 46.0000 1.0000
60.6200 30.0000 1.0000
60.6800 34.0000 1.0000
60.7400 36.0000 1.0000
60.8000 30.0000 1.0000
60.8600 45.0000 1.0000
60.9200 33.0000 1.0000
60.9800 35.0000 1.0000
61.0400 36.0000 1.0000
61.1000 34.0000 1.0000
61.1600 43.0000 1.0000
61.2200 35.0000 1.0000
61.2800 46.0000 1.0000
61.3400 43.0000 1.0000
61.4000 38.0000 1.0000
61.4600 47.0000 1.0000
61.5200 43.0000 1.0000
61.5800 39.0000 1.0000
61.6400 45.0000 1.0000
61.7000 28.0000 1.0000
61.7600 40.0000 1.0000
61.8200 31.0000 1.0000
61.8800 36.0000 1.0000
61.9400 43.0000 1.0000
62.0000 35.0000 1.0000
62.0600 36.0000 1.0000
62.1200 41.0000 1.0000
62.1800 54.0000 1.0000
62.2400 84.0000 1.0000
62.3000 174.0000 1.0000
62.3600 336.0000 1.0000
62.4200 119.0000 1.0000
62.4800 120.0000 1.0000
62.5400 204.0000 1.0000
62.6000 67.0000 1.0000
62.6600 49.0000 1.0000
62.7200 32.0000 1.0000
62.7800 52.0000 1.0000
62.8400 28.0000 1.0000
62.9000 39.0000 1.0000
62.9600 26.0000 1.0000
63.0200 40.0000 1.0000
63.0800 23.0000 1.0000
63.1400 45.0000 1.0000
63.2000 31.0000 1.0000
63.2600 38.0000 1.0000
63.3200 43.0000 1.0000
63.3800 50.0000 1.0000
63.4400 40.0000 1.0000
63.5000 46.0000 1.0000
63.5600 45.0000 1.0000
63.6200 48.0000 1.0000
63.6800 47.0000 1.0000
63.7400 41.0000 1.0000
63.8000 32.0000 1.0000
63.8600 39.0000 1.0000
63.9200 29.0000 1.0000
63.9800 52.0000 1.0000
64.0400 34.0000 1.0000
64.1000 41.0000 1.0000
64.1600 47.0000 1.0000
64.2200 61.0000 1.0000
64.2800 39.0000 1.0000
64.3400 30.0000 1.0000
64.4000 47.0000 1.0000
64.4600 41.0000 1.0000
64.5200 36.0000 1.0000
64.5800 47.0000 1.0000
64.6400 51.0000 1.0000
64.7000 51.0000 1.0000
64.7600 42.0000 1.0000
64.8200 37.0000 1.0000
64.8800 55.0000 1.0000
64.9400 48.0000 1.0000
65.0000 46.0000 1.0000
65.0600 43.0000 1.0000
65.1200 44.0000 1.0000
65.1800 43.0000 1.0000
65.2400 46.0000 1.0000
65.3000 50.0000 1.0000
65.3600 42.0000 1.0000
65.4200 52.0000 1.0000
65.4800 38.0000 1.0000
65.5400 68.0000 1.0000
65.6000 72.0000 1.0000
65.6600 117.0000 1.0000
65.7200 386.0000 1.0000
65.7800 562.0000 1.0000
65.8400 204.0000 1.0000
65.9000 218.0000 1.0000
65.9600 313.0000 1.0000
66.0200 111.0000 1.0000
66.0800 61.0000 1.0000
66.1400 56.0000 1.0000
66.2000 38.0000 1.0000
66.2600 43.0000 1.0000
66.3200 42.0000 1.0000
66.3800 61.0000 1.0000
66.4400 36.0000 1.0000
66.5000 47.0000 1.0000
66.5600 58.0000 1.0000
66.6200 44.0000 1.0000
66.6800 39.0000 1.0000
66.7400 34.0000 1.0000
66.8000 39.0000 1.0000
66.8600 62.0000 1.0000
66.9200 43.0000 1.0000
66.9800 41.0000 1.0000
67.0400 35.0000 1.0000
67.1000 45.0000 1.0000
67.1600 51.0000 1.0000
67.2200 65.0000 1.0000
67.2800 53.0000 1.0000
67.3400 43.0000 1.0000
67.4000 56.0000 1.0000
67.4600 46.0000 1.0000
67.5200 39.0000 1.0000
67.5800 54.0000 1.0000
67.6400 49.0000 1.0000
67.7000 46.0000 1.0000
67.7600 39.0000 1.0000
67.8200 46.0000 1.0000
67.8800 66.0000 1.0000
67.9400 124.0000 1.0000
68.0000 163.0000 1.0000
68.0600 52.0000 1.0000
68.1200 85.0000 1.0000
68.1800 106.0000 1.0000
68.2400 62.0000 1.0000
68.3000 66.0000 1.0000
68.3600 53.0000 1.0000
68.4200 49.0000 1.0000
68.4800 48.0000 1.0000
68.5400 51.0000 1.0000
68.6000 52.0000 1.0000
68.6600 43.0000 1.0000
68.7200 53.0000 1.0000
68.7800 45.0000 1.0000
68.8400 57.0000 1.0000
68.9000 61.0000 1.0000
68.9600 59.0000 1.0000
69.0200 125.0000 1.0000
69.0800 380.0000 1.0000
69.1400 154.0000 1.0000
69.2000 96.0000 1.0000
69.2600 212.0000 1.0000
69.3200 138.0000 1.0000
69.3800 59.0000 1.0000
69.4400 46.0000 1.0000
69.5000 34.0000 1.0000
69.5600 46.0000 1.0000
69.6200 48.0000 1.0000
69.6800 39.0000 1.0000
69.7400 51.0000 1.0000
69.8000 50.0000 1.0000
69.8600 34.0000 1.0000
69.9200 36.0000 1.0000
69.9800 52.0000 1.0000
70.0400 77.0000 1.0000
70.1000 48.0000 1.0000
70.1600 36.0000 1.0000
70.2200 45.0000 1.0000
70.2800 45.0000 1.0000
70.3400 42.0000 1.0000
70.4000 45.0000 1.0000
70.4600 47.0000 1.0000
70.5200 52.0000 1.0000
70.5800 41.0000 1.0000
70.6400 38.0000 1.0000
70.7000 55.0000 1.0000
70.7600 40.0000 1.0000
70.8200 52.0000 1.0000
70.8800 47.0000 1.0000
70.9400 40.0000 1.0000
71.0000 54.0000 1.0000
71.0600 50.0000 1.0000
71.1200 58.0000 1.0000
71.1800 46.0000 1.0000
71.2400 45.0000 1.0000
71.3000 38.0000 1.0000
71.3600 47.0000 1.0000
71.4200 45.0000 1.0000
71.4800 44.0000 1.0000
71.5400 41.0000 1.0000
71.6000 37.0000 1.0000
71.6600 39.0000 1.0000
71.7200 39.0000 1.0000
71.7800 43.0000 1.0000
71.8400 53.0000 1.0000
71.9000 66.0000 1.0000
71.9600 61.0000 1.0000
72.0200 51.0000 1.0000
72.0800 60.0000 1.0000
72.1400 56.0000 1.0000
72.2000 83.0000 1.0000
72.2600 121.0000 1.0000
72.3200 357.0000 1.0000
72.3800 273.0000 1.0000
72.4400 107.0000 1.0000
72.5000 154.0000 1.0000
72.5600 246.0000 1.0000
72.6200 121.0000 1.0000
72.6800 61.0000 1.0000
72.7400 51.0000 1.0000
72.8000 46.0000 1.0000
72.8600 57.0000 1.0000
72.9200 46.0000 1.0000
72.9800 53.0000 1.0000
73.0400 52.0000 1.0000
73.1000 42.0000 1.0000
73.1600 60.0000 1.0000
73.2200 41.0000 1.0000
73.2800 48.0000 1.0000
73.3400 32.0000 1.0000
73.4000 56.0000 1.0000
73.4600 50.0000 1.0000
73.5200 73.0000 1.0000
73.5800 111.0000 1.0000
73.6400 146.0000 1.0000
73.7000 116.0000 1.0000
73.7600 77.0000 1.0000
73.8200 98.0000 1.0000
73.8800 94.0000 1.0000
73.9400 82.0000 1.0000
74.0000 45.0000 1.0000
74.0600 52.0000 1.0000
74.1200 66.0000 1.0000
74.1800 75.0000 1.0000
74.2400 93.0000 1.0000
74.3000 52.0000 1.0000
74.3600 45.0000 1.0000
74.4200 65.0000 1.0000
74.4800 66.0000 1.0000
74.5400 57.0000 1.0000
74.6000 54.0000 1.0000
74.6600 52.0000 1.0000
74.7200 41.0000 1.0000
74.7800 57.0000 1.0000
74.8400 45.0000 1.0000
74.9000 57.0000 1.0000
74.9600 43.0000 1.0000
75.0200 60.0000 1.0000
75.0800 47.0000 1.0000
75.1400 54.0000 1.0000
75.2000 67.0000 1.0000
75.2600 62.0000 1.0000
75.3200 92.0000 1.0000
75.3800 126.0000 1.0000
75.4400 210.0000 1.0000
75.5000 703.0000 1.0000
75.5600 877.0000 1.0000
75.6200 302.0000 1.0000
75.6800 245.0000 1.0000
75.7400 535.0000 1.0000
75.8000 390.0000 1.0000
75.8600 138.0000 1.0000
75.9200 79.0000 1.0000
75.9800 63.0000 1.0000
76.0400 49.0000 1.0000
76.1000 56.0000 1.0000
76.1600 49.0000 1.0000
76.2200 56.0000 1.0000
76.2800 52.0000 1.0000
76.3400 55.0000 1.0000
76.4000 39.0000 1.0000
76.4600 55.0000 1.0000
76.5200 75.0000 1.0000
76.5800 96.0000 1.0000
76.6400 103.0000 1.0000
76.7000 108.0000 1.0000
76.7600 188.0000 1.0000
76.8200 443.0000 1.0000
76.8800 1022.0000 1.0000
76.9400 1087.0000 1.0000
77.0000 724.0000 1.0000
77.0600 464.0000 1.0000
77.1200 631.0000 1.0000
77.1800 581.0000 1.0000
77.2400 338.0000 1.0000
77.3000 126.0000 1.0000
77.3600 69.0000 1.0000
77.4200 58.0000 1.0000
77.4800 67.0000 1.0000
77.5400 53.0000 1.0000
77.6000 42.0000 1.0000
77.6600 52.0000 1.0000
77.7200 61.0000 1.0000
77.7800 59.0000 1.0000
77.8400 65.0000 1.0000
77.9000 66.0000 1.0000
77.9600 65.0000 1.0000
78.0200 48.0000 1.0000
78.0800 49.0000 1.0000
78.1400 49.0000 1.0000
78.2000 37.0000 1.0000
78.2600 55.0000 1.0000
78.3200 52.0000 1.0000
78.3800 41.0000 1.0000
78.4400 42.0000 1.0000
78.5000 39.0000 1.0000
78.5600 40.0000 1.0000
78.6200 57.0000 1.0000
78.6800 44.0000 1.0000
78.7400 43.0000 1.0000
78.8000 45.0000 1.0000
78.8600 39.0000 1.0000
78.9200 50.0000 1.0000
78.9800 53.0000 1.0000
79.0400 37.0000 1.0000
79.1000 46.0000 1.0000
79.1600 55.0000 1.0000
79.2200 47.0000 1.0000
79.2800 52.0000 1.0000
79.3400 57.0000 1.0000
79.4000 46.0000 1.0000
79.4600 47.0000 1.0000
79.5200 45.0000 1.0000
79.5800 36.0000 1.0000
79.6400 39.0000 1.0000
79.7000 56.0000 1.0000
79.7600 37.0000 1.0000
79.8200 51.0000 1.0000
79.8800 49.0000 1.0000
79.9400 48.0000 1.0000
80.0000 47.0000 1.0000
80.0600 52.0000 1.0000
80.1200 42.0000 1.0000
80.1800 45.0000 1.0000
80.2400 44.0000 1.0000
80.3000 39.0000 1.0000
80.3600 64.0000 1.0000
80.4200 61.0000 1.0000
80.4800 72.0000 1.0000
80.5400 109.0000 1.0000
80.6000 111.0000 1.0000
80.6600 79.0000 1.0000
80.7200 93.0000 1.0000
80.7800 74.0000 1.0000
80.8400 74.0000 1.0000
80.9000 66.0000 1.0000
80.9600 77.0000 1.0000
81.0200 55.0000 1.0000
81.0800 54.0000 1.0000
81.1400 56.0000 1.0000
81.2000 43.0000 1.0000
81.2600 47.0000 1.0000
81.3200 49.0000 1.0000
81.3800 46.0000 1.0000
81.4400 45.0000 1.0000
81.5000 53.0000 1.0000
81.5600 62.0000 1.0000
81.6200 59.0000 1.0000
81.6800 99.0000 1.0000
81.7400 188.0000 1.0000
81.8000 330.0000 1.0000
81.8600 262.0000 1.0000
81.9200 132.0000 1.0000
81.9800 115.0000 1.0000
82.0400 168.0000 1.0000
82.1000 137.0000 1.0000
82.1600 95.0000 1.0000
82.2200 53.0000 1.0000
82.2800 52.0000 1.0000
82.3400 42.0000 1.0000
82.4000 47.0000 1.0000
82.4600 42.0000 1.0000
82.5200 44.0000 1.0000
82.5800 50.0000 1.0000
82.6400 46.0000 1.0000
82.7000 54.0000 1.0000
82.7600 39.0000 1.0000
82.8200 47.0000 1.0000
82.8800 46.0000 1.0000
82.9400 45.0000 1.0000
83.0000 43.0000 1.0000
83.0600 37.0000 1.0000
83.1200 51.0000 1.0000
83.1800 50.0000 1.0000
83.2400 51.0000 1.0000
83.3000 43.0000 1.0000
83.3600 46.0000 1.0000
83.4200 57.0000 1.0000
83.4800 41.0000 1.0000
83.5400 63.0000 1.0000
83.6000 40.0000 1.0000
83.6600 41.0000 1.0000
83.7200 49.0000 1.0000
83.7800 40.0000 1.0000
83.8400 53.0000 1.0000
83.9000 46.0000 1.0000
83.9600 41.0000 1.0000
84.0200 48.0000 1.0000
84.0800 39.0000 1.0000
84.1400 45.0000 1.0000
84.2000 36.0000 1.0000
84.2600 36.0000 1.0000
84.3200 40.0000 1.0000
84.3800 46.0000 1.0000
84.4400 49.0000 1.0000
84.5000 47.0000 1.0000
84.5600 42.0000 1.0000
84.6200 48.0000 1.0000
84.6800 34.0000 1.0000
84.7400 48.0000 1.0000
84.8000 50.0000 1.0000
84.8600 61.0000 1.0000
84.9200 68.0000 1.0000
84.9800 46.0000 1.0000
85.0400 48.0000 1.0000
85.1000 56.0000 1.0000
85.1600 60.0000 1.0000
85.2200 52.0000 1.0000
85.2800 57.0000 1.0000
85.3400 58.0000 1.0000
85.4000 54.0000 1.0000
85.4600 59.0000 1.0000
85.5200 61.0000 1.0000
85.5800 42.0000 1.0000
85.6400 65.0000 1.0000
85.7000 42.0000 1.0000
85.7600 44.0000 1.0000
85.8200 39.0000 1.0000
85.8800 40.0000 1.0000
85.9400 44.0000 1.0000
86.0000 44.0000 1.0000
86.0600 55.0000 1.0000
86.1200 43.0000 1.0000
86.1800 49.0000 1.0000
86.2400 47.0000 1.0000
86.3000 33.0000 1.0000
86.3600 46.0000 1.0000
86.4200 50.0000 1.0000
86.4800 46.0000 1.0000
86.5400 48.0000 1.0000
86.6000 47.0000 1.0000
86.6600 35.0000 1.0000
86.7200 41.0000 1.0000
86.7800 44.0000 1.0000
86.8400 49.0000 1.0000
86.9000 39.0000 1.0000
86.9600 51.0000 1.0000
87.0200 41.0000 1.0000
87.0800 48.0000 1.0000
87.1400 46.0000 1.0000
87.2000 53.0000 1.0000
87.2600 51.0000 1.0000
87.3200 46.0000 1.0000
87.3800 57.0000 1.0000
87.4400 58.0000 1.0000
87.5000 61.0000 1.0000
87.5600 47.0000 1.0000
87.6200 42.0000 1.0000
87.6800 55.0000 1.0000
87.7400 57.0000 1.0000
87.8000 75.0000 1.0000
87.8600 99.0000 1.0000
87.9200 149.0000 1.0000
87.9800 261.0000 1.0000
88.0400 151.0000 1.0000
88.1000 95.0000 1.0000
88.1600 86.0000 1.0000
88.2200 135.0000 1.0000
88.2800 147.0000 1.0000
88.3400 83.0000 1.0000
88.4000 59.0000 1.0000
88.4600 56.0000 1.0000
88.5200 49.0000 1.0000
88.5800 56.0000 1.0000
88.6400 45.0000 1.0000
88.7000 37.0000 1.0000
88.7600 44.0000 1.0000
88.8200 55.0000 1.0000
88.8800 52.0000 1.0000
88.9400 45.0000 1.0000
89.0000 47.0000 1.0000
89.0600 44.0000 1.0000
89.1200 38.0000 1.0000
89.1800 45.0000 1.0000
89.2400 48.0000 1.0000
89.3000 64.0000 1.0000
89.3600 50.0000 1.0000
89.4200 59.0000 1.0000
89.4800 38.0000 1.0000
89.5400 44.0000 1.0000
89.6000 42.0000 1.0000
89.6600 45.0000 1.0000
89.7200 43.0000 1.0000
89.7800 48.0000 1.0000
89.8400 55.0000 1.0000
89.9000 48.0000 1.0000
89.9600 48.0000 1.0000
89.9800 51.0000 1.0000
*RAS_INT_END
*RAS_DATA_END