File: text_folda/Al1Si54Ru45_ASR66_568h.ras
*RAS_DATA_START
*RAS_HEADER_START
*DISP_FMT_X "%.2f"
*DISP_FMT_Y "%.0f"
*DISP_FULLSCALE "143900.0000000000"
*DISP_LINE_COLOR "255.0000000000"
*DISP_LINE_STYLE "0.0000000000"
*DISP_LINE_WIDTH "0.2500000000"
*DISP_NOTE "測定データ-9"
*DISP_OFFSET_Y "0.0000000000"
*DISP_PEAKSEARCH_UNIT_Y "cps"
*DISP_RANGE_BOTTOM "0.0000000000"
*DISP_RANGE_LEFT "5.0000000000"
*DISP_RANGE_LOGCUTOFF "0.0100000000"
*DISP_RANGE_RIGHT "90.0000000000"
*DISP_RANGE_TOP "143900.0000000000"
*DISP_SCALE_MODE_Y "0.0000000000"
*DISP_TAB_NAME "2θ/θ"
*DISP_TITLE_Y "強度"
*DISP_UNIT_Y "cps"
*DISP_WINDOW_NAME "MSG_MACROENGINE"
*FILE_COMMENT " "
*FILE_MD5 ""
*FILE_MEMO " "
*FILE_OPERATOR "User1"
*FILE_SAMPLE " "
*FILE_TYPE "RAS_RAW"
*FILE_USERGROUP "システムユーザー"
*FILE_VERSION "1.0000000000"
*HW_ATTACHMENT_ID "ATT0025"
*HW_ATTACHMENT_NAME "標準|Standard"
*HW_COUNTER_ID-0 "CUT0041"
*HW_COUNTER_ID-1 "CUT0020"
*HW_COUNTER_ID-2 ""
*HW_COUNTER_ID-3 "CSL0021"
*HW_COUNTER_ID-4 "CMC0021"
*HW_COUNTER_NAME-0 "D/teX Ultra 250|D/teX Ultra 250"
*HW_COUNTER_NAME-1 "None|None"
*HW_COUNTER_NAME-2 ""
*HW_COUNTER_NAME-3 "BBM|BBM"
*HW_COUNTER_NAME-4 "検出器モノクロメータ|Detector monochromator"
*HW_COUNTER_SELECT_NAME "D/teX Ultra 250|D/teX Ultra 250"
*HW_GONIOMETER_ID "GON0023"
*HW_GONIOMETER_NAME "SmartLab|SmartLab"
*HW_GONIOMETER_RADIUS-0 "90.0"
*HW_GONIOMETER_RADIUS-1 "114.0"
*HW_GONIOMETER_RADIUS-2 "190.0"
*HW_GONIOMETER_RADIUS-3 "300.0"
*HW_GONIOMETER_RADIUS-4 "187.0"
*HW_GONIOMETER_RADIUS-5 "300.0"
*HW_GONIOMETER_RADIUS-6 "113.0"
*HW_GONIOMETER_RADIUS-7 "331.0"
*HW_I_OPT_ID-0 "CBO0023"
*HW_I_OPT_ID-1 "ICR0023"
*HW_I_OPT_ID-2 "ISL0021"
*HW_I_OPT_ID-3 "ISO0021"
*HW_I_OPT_ID-4 "IAD0021"
*HW_I_OPT_ID-5 "IPR0001"
*HW_I_OPT_NAME-0 "オープン-BBユニット|Open-BB unit"
*HW_I_OPT_NAME-1 "標準入射光学ユニット|Standard incident optical unit"
*HW_I_OPT_NAME-2 "標準入射スリットボックス|Standard incident slit box"
*HW_I_OPT_NAME-3 "入射平行スリット|Incident parallel slit"
*HW_I_OPT_NAME-4 "長手制限スリット|Length limiting slit"
*HW_I_OPT_NAME-5 "None|None"
*HW_R_ATTENUATER_AUTOMODE "0"
*HW_R_OPT_ID-0 "RSS0021"
*HW_R_OPT_ID-1 "RCR0023"
*HW_R_OPT_ID-2 "RSO0021"
*HW_R_OPT_ID-3 "RRS0021"
*HW_R_OPT_ID-4 "ATN0021"
*HW_R_OPT_ID-5 "RFL0021"
*HW_R_OPT_ID-6 "RAD0021"
*HW_R_OPT_NAME-0 "標準受光スリットボックス1|Standard receiving slit box # 1"
*HW_R_OPT_NAME-1 "標準受光光学ユニット1|Standard receiving unit # 1"
*HW_R_OPT_NAME-2 "標準受光光学ユニット2|Standard receiving optical unit # 2"
*HW_R_OPT_NAME-3 "標準受光スリットボックス2|Standard receiving slit box # 2"
*HW_R_OPT_NAME-4 "標準アッテネータ|Standard Attenuator"
*HW_R_OPT_NAME-5 "Cu Kβ|Cu K-beta"
*HW_R_OPT_NAME-6 "調整用受光スリット|Alignment receiving slit"
*HW_SAMPLE_HOLDER_ID "SMP0023"
*HW_SAMPLE_HOLDER_NAME "標準Zステージ|Standard Z stage"
*HW_XG_CURRENT_MAX "50"
*HW_XG_CURRENT_MIN "2"
*HW_XG_CURRENT_RESOLUTION "2"
*HW_XG_CURRENT_UNIT "mA"
*HW_XG_FOCUS "1mm x 10mm"
*HW_XG_FOCUS_TYPE "Normal"
*HW_XG_ID ""
*HW_XG_NAME "3kW 封入管(ID:1200)|3kW Sealed tube(ID:1200)"
*HW_XG_TARGET_ATOMIC_NUMBER "29.0000000000"
*HW_XG_TARGET_NAME "Cu"
*HW_XG_TYPE "Hermetic"
*HW_XG_VOLTAGE_MAX "60"
*HW_XG_VOLTAGE_MIN "20"
*HW_XG_VOLTAGE_RESOLUTION "2"
*HW_XG_VOLTAGE_UNIT "kV"
*HW_XG_WATT_MAX "2"
*HW_XG_WATT_UNIT "kW"
*HW_XG_WAVE_LENGTH_ALPHA1 "1.540593"
*HW_XG_WAVE_LENGTH_ALPHA2 "1.544414"
*HW_XG_WAVE_LENGTH_BETA "1.392250"
*MEAS_COND_AXIS_NAME-0 "2θ/θ"
*MEAS_COND_AXIS_NAME-1 "2θ"
*MEAS_COND_AXIS_NAME-2 "ω"
*MEAS_COND_AXIS_NAME-3 "Z"
*MEAS_COND_AXIS_NAME-4 "2θ/ω"
*MEAS_COND_AXIS_NAME-5 "θs"
*MEAS_COND_AXIS_NAME-6 "θd"
*MEAS_COND_AXIS_NAME-7 "Ts"
*MEAS_COND_AXIS_NAME-8 "CBO選択スリット"
*MEAS_COND_AXIS_NAME-9 "M"
*MEAS_COND_AXIS_NAME-10 "入射平行スリット"
*MEAS_COND_AXIS_NAME-11 "入射スリット"
*MEAS_COND_AXIS_NAME-12 ""
*MEAS_COND_AXIS_NAME-13 "Zs"
*MEAS_COND_AXIS_NAME-14 "入射光学素子"
*MEAS_COND_AXIS_NAME-15 "長手制限スリット"
*MEAS_COND_AXIS_NAME-16 "センタースリット"
*MEAS_COND_AXIS_NAME-17 "フィルター"
*MEAS_COND_AXIS_NAME-18 "受光スリット1"
*MEAS_COND_AXIS_NAME-19 "受光スリット2"
*MEAS_COND_AXIS_NAME-20 "受光光学素子"
*MEAS_COND_AXIS_NAME-21 "受光平行スリット"
*MEAS_COND_AXIS_NAME-22 "調整用受光スリット"
*MEAS_COND_AXIS_NAME-23 ""
*MEAS_COND_AXIS_NAME-24 ""
*MEAS_COND_AXIS_NAME-25 "Zd"
*MEAS_COND_AXIS_NAME-26 "アッテネータ"
*MEAS_COND_AXIS_NAME-27 "検出器モノクロメータ"
*MEAS_COND_AXIS_NAME-28 "モノクロメータスリット"
*MEAS_COND_AXIS_NAME-29 "プライマリビーム"
*MEAS_COND_AXIS_NAME-30 "PHA"
*MEAS_COND_AXIS_NAME_INTERNAL-0 "TwoThetaTheta"
*MEAS_COND_AXIS_NAME_INTERNAL-1 "TwoTheta"
*MEAS_COND_AXIS_NAME_INTERNAL-2 "Omega"
*MEAS_COND_AXIS_NAME_INTERNAL-3 "Z"
*MEAS_COND_AXIS_NAME_INTERNAL-4 "TwoThetaOmega"
*MEAS_COND_AXIS_NAME_INTERNAL-5 "ThetaS"
*MEAS_COND_AXIS_NAME_INTERNAL-6 "ThetaD"
*MEAS_COND_AXIS_NAME_INTERNAL-7 "Ts"
*MEAS_COND_AXIS_NAME_INTERNAL-8 "CBO"
*MEAS_COND_AXIS_NAME_INTERNAL-9 "CBO-M"
*MEAS_COND_AXIS_NAME_INTERNAL-10 "IncidentSollerSlit"
*MEAS_COND_AXIS_NAME_INTERNAL-11 "IncidentSlitBox"
*MEAS_COND_AXIS_NAME_INTERNAL-12 "IncidentSlitBox-_Axis"
*MEAS_COND_AXIS_NAME_INTERNAL-13 "Zs"
*MEAS_COND_AXIS_NAME_INTERNAL-14 "IncidentMonochromator"
*MEAS_COND_AXIS_NAME_INTERNAL-15 "IncidentAxdSlit"
*MEAS_COND_AXIS_NAME_INTERNAL-16 "CenterSlit"
*MEAS_COND_AXIS_NAME_INTERNAL-17 "Filter"
*MEAS_COND_AXIS_NAME_INTERNAL-18 "ReceivingSlitBox1"
*MEAS_COND_AXIS_NAME_INTERNAL-19 "ReceivingSlitBox2"
*MEAS_COND_AXIS_NAME_INTERNAL-20 "ReceivingOptics"
*MEAS_COND_AXIS_NAME_INTERNAL-21 "ReceivingSollerSlit"
*MEAS_COND_AXIS_NAME_INTERNAL-22 "ReceivingAxdSlit"
*MEAS_COND_AXIS_NAME_INTERNAL-23 "ReceivingSlitBox1-_Axis"
*MEAS_COND_AXIS_NAME_INTERNAL-24 "ReceivingSlitBox2-_Axis"
*MEAS_COND_AXIS_NAME_INTERNAL-25 "ReceivingSlitBox2-Zd"
*MEAS_COND_AXIS_NAME_INTERNAL-26 "Attenuator"
*MEAS_COND_AXIS_NAME_INTERNAL-27 "CounterMonochromator"
*MEAS_COND_AXIS_NAME_INTERNAL-28 "CounterSlit"
*MEAS_COND_AXIS_NAME_INTERNAL-29 "IncidentPrimary"
*MEAS_COND_AXIS_NAME_INTERNAL-30 "PHA"
*MEAS_COND_AXIS_NAME_MAGICNO-0 "83951616.0000000000"
*MEAS_COND_AXIS_NAME_MAGICNO-1 "268632064.0000000000"
*MEAS_COND_AXIS_NAME_MAGICNO-2 "268500992.0000000000"
*MEAS_COND_AXIS_NAME_MAGICNO-3 "285278208.0000000000"
*MEAS_COND_AXIS_NAME_MAGICNO-4 "83951616.0000000000"
*MEAS_COND_AXIS_NAME_MAGICNO-5 "131072.0000000000"
*MEAS_COND_AXIS_NAME_MAGICNO-6 "131072.0000000000"
*MEAS_COND_AXIS_NAME_MAGICNO-7 "318898176.0000000000"
*MEAS_COND_AXIS_NAME_MAGICNO-8 "20971521.0000000000"
*MEAS_COND_AXIS_NAME_MAGICNO-9 "285343744.0000000000"
*MEAS_COND_AXIS_NAME_MAGICNO-10 "20971521.0000000000"
*MEAS_COND_AXIS_NAME_MAGICNO-11 "22020097.0000000000"
*MEAS_COND_AXIS_NAME_MAGICNO-12 "25165824.0000000000"
*MEAS_COND_AXIS_NAME_MAGICNO-13 "318898176.0000000000"
*MEAS_COND_AXIS_NAME_MAGICNO-14 "1.0000000000"
*MEAS_COND_AXIS_NAME_MAGICNO-15 "20971521.0000000000"
*MEAS_COND_AXIS_NAME_MAGICNO-16 "20971521.0000000000"
*MEAS_COND_AXIS_NAME_MAGICNO-17 "20971521.0000000000"
*MEAS_COND_AXIS_NAME_MAGICNO-18 "23068673.0000000000"
*MEAS_COND_AXIS_NAME_MAGICNO-19 "23068673.0000000000"
*MEAS_COND_AXIS_NAME_MAGICNO-20 "20971521.0000000000"
*MEAS_COND_AXIS_NAME_MAGICNO-21 "20971521.0000000000"
*MEAS_COND_AXIS_NAME_MAGICNO-22 "20971521.0000000000"
*MEAS_COND_AXIS_NAME_MAGICNO-23 "25165824.0000000000"
*MEAS_COND_AXIS_NAME_MAGICNO-24 "25165824.0000000000"
*MEAS_COND_AXIS_NAME_MAGICNO-25 "285343744.0000000000"
*MEAS_COND_AXIS_NAME_MAGICNO-26 "17301505.0000000000"
*MEAS_COND_AXIS_NAME_MAGICNO-27 "20971521.0000000000"
*MEAS_COND_AXIS_NAME_MAGICNO-28 "20971521.0000000000"
*MEAS_COND_AXIS_NAME_MAGICNO-29 "20971521.0000000000"
*MEAS_COND_AXIS_NAME_MAGICNO-30 "0.0000000000"
*MEAS_COND_AXIS_OFFSET-0 "-"
*MEAS_COND_AXIS_OFFSET-1 "0.1576000000"
*MEAS_COND_AXIS_OFFSET-2 "0.3837000000"
*MEAS_COND_AXIS_OFFSET-3 "-"
*MEAS_COND_AXIS_OFFSET-4 "-"
*MEAS_COND_AXIS_OFFSET-5 "0.3837000000"
*MEAS_COND_AXIS_OFFSET-6 "-0.2261000000"
*MEAS_COND_AXIS_OFFSET-7 "-"
*MEAS_COND_AXIS_OFFSET-8 "-"
*MEAS_COND_AXIS_OFFSET-9 "-"
*MEAS_COND_AXIS_OFFSET-10 "-"
*MEAS_COND_AXIS_OFFSET-11 "-"
*MEAS_COND_AXIS_OFFSET-12 "-"
*MEAS_COND_AXIS_OFFSET-13 "-"
*MEAS_COND_AXIS_OFFSET-14 "-"
*MEAS_COND_AXIS_OFFSET-15 "-"
*MEAS_COND_AXIS_OFFSET-16 "-"
*MEAS_COND_AXIS_OFFSET-17 "-"
*MEAS_COND_AXIS_OFFSET-18 "-"
*MEAS_COND_AXIS_OFFSET-19 "-"
*MEAS_COND_AXIS_OFFSET-20 "-"
*MEAS_COND_AXIS_OFFSET-21 "-"
*MEAS_COND_AXIS_OFFSET-22 "-"
*MEAS_COND_AXIS_OFFSET-23 "-"
*MEAS_COND_AXIS_OFFSET-24 "-"
*MEAS_COND_AXIS_OFFSET-25 "-"
*MEAS_COND_AXIS_OFFSET-26 "-"
*MEAS_COND_AXIS_OFFSET-27 "-"
*MEAS_COND_AXIS_OFFSET-28 "-"
*MEAS_COND_AXIS_OFFSET-29 "-"
*MEAS_COND_AXIS_OFFSET-30 "-"
*MEAS_COND_AXIS_POSITION-0 "0.0000000000"
*MEAS_COND_AXIS_POSITION-1 "0.0000000000"
*MEAS_COND_AXIS_POSITION-2 "0.0000000000"
*MEAS_COND_AXIS_POSITION-3 "-0.1000000000"
*MEAS_COND_AXIS_POSITION-4 "0.0000000000"
*MEAS_COND_AXIS_POSITION-5 "0.0000000000"
*MEAS_COND_AXIS_POSITION-6 "0.0000000000"
*MEAS_COND_AXIS_POSITION-7 "0.0000000000"
*MEAS_COND_AXIS_POSITION-8 "BB"
*MEAS_COND_AXIS_POSITION-9 "0.0000000000"
*MEAS_COND_AXIS_POSITION-10 "Soller_slit_5.0deg"
*MEAS_COND_AXIS_POSITION-11 "2/3deg"
*MEAS_COND_AXIS_POSITION-12 "2.2088000000"
*MEAS_COND_AXIS_POSITION-13 "0.3640600000"
*MEAS_COND_AXIS_POSITION-14 "0.0000000000"
*MEAS_COND_AXIS_POSITION-15 "5.0mm"
*MEAS_COND_AXIS_POSITION-16 "None"
*MEAS_COND_AXIS_POSITION-17 "Cu_K-beta"
*MEAS_COND_AXIS_POSITION-18 "20.000mm"
*MEAS_COND_AXIS_POSITION-19 "20.000mm"
*MEAS_COND_AXIS_POSITION-20 "No_unit"
*MEAS_COND_AXIS_POSITION-21 "Soller_slit_5.0deg"
*MEAS_COND_AXIS_POSITION-22 "None"
*MEAS_COND_AXIS_POSITION-23 "20.0000000000"
*MEAS_COND_AXIS_POSITION-24 "20.0000000000"
*MEAS_COND_AXIS_POSITION-25 "0.1487500000"
*MEAS_COND_AXIS_POSITION-26 "Open"
*MEAS_COND_AXIS_POSITION-27 "None"
*MEAS_COND_AXIS_POSITION-28 "None"
*MEAS_COND_AXIS_POSITION-29 "None"
*MEAS_COND_AXIS_POSITION-30 "44.0000000000"
*MEAS_COND_AXIS_UNIT-0 "deg"
*MEAS_COND_AXIS_UNIT-1 "deg"
*MEAS_COND_AXIS_UNIT-2 "deg"
*MEAS_COND_AXIS_UNIT-3 "mm"
*MEAS_COND_AXIS_UNIT-4 "deg"
*MEAS_COND_AXIS_UNIT-5 "deg"
*MEAS_COND_AXIS_UNIT-6 "deg"
*MEAS_COND_AXIS_UNIT-7 "mm"
*MEAS_COND_AXIS_UNIT-8 ""
*MEAS_COND_AXIS_UNIT-9 "pulse"
*MEAS_COND_AXIS_UNIT-10 ""
*MEAS_COND_AXIS_UNIT-11 ""
*MEAS_COND_AXIS_UNIT-12 "mm"
*MEAS_COND_AXIS_UNIT-13 "mm"
*MEAS_COND_AXIS_UNIT-14 ""
*MEAS_COND_AXIS_UNIT-15 ""
*MEAS_COND_AXIS_UNIT-16 ""
*MEAS_COND_AXIS_UNIT-17 ""
*MEAS_COND_AXIS_UNIT-18 ""
*MEAS_COND_AXIS_UNIT-19 ""
*MEAS_COND_AXIS_UNIT-20 ""
*MEAS_COND_AXIS_UNIT-21 ""
*MEAS_COND_AXIS_UNIT-22 ""
*MEAS_COND_AXIS_UNIT-23 "mm"
*MEAS_COND_AXIS_UNIT-24 "mm"
*MEAS_COND_AXIS_UNIT-25 "mm"
*MEAS_COND_AXIS_UNIT-26 ""
*MEAS_COND_AXIS_UNIT-27 ""
*MEAS_COND_AXIS_UNIT-28 ""
*MEAS_COND_AXIS_UNIT-29 ""
*MEAS_COND_AXIS_UNIT-30 "div"
*MEAS_COND_COUNTER_CNTLOSS_CORR "0.0000000000"
*MEAS_COND_COUNTER_PHABASE "44.0000000000"
*MEAS_COND_COUNTER_PHAWINDOW "9.0000000000"
*MEAS_COND_COUNTER_PHA_UNIT "div"
*MEAS_COND_COUNTER_TAUDIFF "0.0000000000"
*MEAS_COND_COUNTER_TAUINT "0.0000000000"
*MEAS_COND_IRRADIATION_MODE "OFF"
*MEAS_COND_IRRADIATION_WIDTH ""
*MEAS_COND_OPT_ATTR "集中法"
*MEAS_COND_OPT_NAME "@集中法"
*MEAS_COND_UNSYMMETRIC_MODE "OFF"
*MEAS_COND_XG_CURRENT "30.0000000000"
*MEAS_COND_XG_VOLTAGE "40.0000000000"
*MEAS_COND_XG_WAVE_TYPE "Ka"
*MEAS_DATA_COUNT "4250.0000000000"
*MEAS_SCAN_AXIS_X "2θ/θ"
*MEAS_SCAN_AXIS_X_INTERNAL "TwoThetaTheta"
*MEAS_SCAN_END_TIME "05/21/21 11:44:19"
*MEAS_SCAN_MODE "CONTINUOUS"
*MEAS_SCAN_MONITOR "0"
*MEAS_SCAN_RESOLUTION_X "0.0002"
*MEAS_SCAN_SPEED "20.0"
*MEAS_SCAN_SPEED_UNIT "deg/min"
*MEAS_SCAN_START "5.0000000000"
*MEAS_SCAN_START_TIME "05/21/21 11:39:29"
*MEAS_SCAN_STEP "0.0200000000"
*MEAS_SCAN_STOP "90.0000000000"
*MEAS_SCAN_UNIT_X "deg"
*MEAS_SCAN_UNIT_Y "counts"
*RAS_HEADER_END
*RAS_INT_START
5.0000 183.0000 1.0000
5.0600 186.0000 1.0000
5.1200 178.0000 1.0000
5.1800 211.0000 1.0000
5.2400 169.0000 1.0000
5.3000 178.0000 1.0000
5.3600 190.0000 1.0000
5.4200 209.0000 1.0000
5.4800 185.0000 1.0000
5.5400 180.0000 1.0000
5.6000 180.0000 1.0000
5.6600 208.0000 1.0000
5.7200 191.0000 1.0000
5.7800 176.0000 1.0000
5.8400 185.0000 1.0000
5.9000 176.0000 1.0000
5.9600 222.0000 1.0000
6.0200 202.0000 1.0000
6.0800 199.0000 1.0000
6.1400 162.0000 1.0000
6.2000 197.0000 1.0000
6.2600 191.0000 1.0000
6.3200 209.0000 1.0000
6.3800 179.0000 1.0000
6.4400 176.0000 1.0000
6.5000 168.0000 1.0000
6.5600 195.0000 1.0000
6.6200 197.0000 1.0000
6.6800 198.0000 1.0000
6.7400 205.0000 1.0000
6.8000 193.0000 1.0000
6.8600 167.0000 1.0000
6.9200 183.0000 1.0000
6.9800 176.0000 1.0000
7.0400 158.0000 1.0000
7.1000 201.0000 1.0000
7.1600 175.0000 1.0000
7.2200 158.0000 1.0000
7.2800 199.0000 1.0000
7.3400 173.0000 1.0000
7.4000 199.0000 1.0000
7.4600 176.0000 1.0000
7.5200 188.0000 1.0000
7.5800 179.0000 1.0000
7.6400 170.0000 1.0000
7.7000 168.0000 1.0000
7.7600 178.0000 1.0000
7.8200 161.0000 1.0000
7.8800 155.0000 1.0000
7.9400 154.0000 1.0000
8.0000 184.0000 1.0000
8.0600 174.0000 1.0000
8.1200 159.0000 1.0000
8.1800 170.0000 1.0000
8.2400 154.0000 1.0000
8.3000 162.0000 1.0000
8.3600 166.0000 1.0000
8.4200 158.0000 1.0000
8.4800 165.0000 1.0000
8.5400 173.0000 1.0000
8.6000 192.0000 1.0000
8.6600 146.0000 1.0000
8.7200 141.0000 1.0000
8.7800 154.0000 1.0000
8.8400 162.0000 1.0000
8.9000 145.0000 1.0000
8.9600 176.0000 1.0000
9.0200 156.0000 1.0000
9.0800 135.0000 1.0000
9.1400 148.0000 1.0000
9.2000 154.0000 1.0000
9.2600 140.0000 1.0000
9.3200 150.0000 1.0000
9.3800 122.0000 1.0000
9.4400 168.0000 1.0000
9.5000 163.0000 1.0000
9.5600 168.0000 1.0000
9.6200 154.0000 1.0000
9.6800 161.0000 1.0000
9.7400 142.0000 1.0000
9.8000 167.0000 1.0000
9.8600 149.0000 1.0000
9.9200 148.0000 1.0000
9.9800 157.0000 1.0000
10.0400 157.0000 1.0000
10.1000 137.0000 1.0000
10.1600 163.0000 1.0000
10.2200 140.0000 1.0000
10.2800 144.0000 1.0000
10.3400 151.0000 1.0000
10.4000 165.0000 1.0000
10.4600 139.0000 1.0000
10.5200 146.0000 1.0000
10.5800 144.0000 1.0000
10.6400 149.0000 1.0000
10.7000 147.0000 1.0000
10.7600 147.0000 1.0000
10.8200 119.0000 1.0000
10.8800 140.0000 1.0000
10.9400 144.0000 1.0000
11.0000 139.0000 1.0000
11.0600 138.0000 1.0000
11.1200 143.0000 1.0000
11.1800 142.0000 1.0000
11.2400 152.0000 1.0000
11.3000 138.0000 1.0000
11.3600 125.0000 1.0000
11.4200 128.0000 1.0000
11.4800 114.0000 1.0000
11.5400 139.0000 1.0000
11.6000 127.0000 1.0000
11.6600 128.0000 1.0000
11.7200 135.0000 1.0000
11.7800 133.0000 1.0000
11.8400 130.0000 1.0000
11.9000 140.0000 1.0000
11.9600 130.0000 1.0000
12.0200 127.0000 1.0000
12.0800 133.0000 1.0000
12.1400 144.0000 1.0000
12.2000 139.0000 1.0000
12.2600 111.0000 1.0000
12.3200 140.0000 1.0000
12.3800 136.0000 1.0000
12.4400 125.0000 1.0000
12.5000 119.0000 1.0000
12.5600 116.0000 1.0000
12.6200 118.0000 1.0000
12.6800 126.0000 1.0000
12.7400 134.0000 1.0000
12.8000 140.0000 1.0000
12.8600 119.0000 1.0000
12.9200 117.0000 1.0000
12.9800 116.0000 1.0000
13.0400 114.0000 1.0000
13.1000 132.0000 1.0000
13.1600 124.0000 1.0000
13.2200 118.0000 1.0000
13.2800 138.0000 1.0000
13.3400 131.0000 1.0000
13.4000 111.0000 1.0000
13.4600 125.0000 1.0000
13.5200 121.0000 1.0000
13.5800 147.0000 1.0000
13.6400 105.0000 1.0000
13.7000 112.0000 1.0000
13.7600 115.0000 1.0000
13.8200 114.0000 1.0000
13.8800 102.0000 1.0000
13.9400 124.0000 1.0000
14.0000 101.0000 1.0000
14.0600 129.0000 1.0000
14.1200 112.0000 1.0000
14.1800 109.0000 1.0000
14.2400 101.0000 1.0000
14.3000 106.0000 1.0000
14.3600 111.0000 1.0000
14.4200 119.0000 1.0000
14.4800 128.0000 1.0000
14.5400 107.0000 1.0000
14.6000 106.0000 1.0000
14.6600 101.0000 1.0000
14.7200 117.0000 1.0000
14.7800 126.0000 1.0000
14.8400 94.0000 1.0000
14.9000 123.0000 1.0000
14.9600 114.0000 1.0000
15.0200 104.0000 1.0000
15.0800 107.0000 1.0000
15.1400 114.0000 1.0000
15.2000 117.0000 1.0000
15.2600 121.0000 1.0000
15.3200 107.0000 1.0000
15.3800 99.0000 1.0000
15.4400 100.0000 1.0000
15.5000 122.0000 1.0000
15.5600 102.0000 1.0000
15.6200 97.0000 1.0000
15.6800 101.0000 1.0000
15.7400 111.0000 1.0000
15.8000 109.0000 1.0000
15.8600 104.0000 1.0000
15.9200 95.0000 1.0000
15.9800 99.0000 1.0000
16.0400 101.0000 1.0000
16.1000 107.0000 1.0000
16.1600 112.0000 1.0000
16.2200 82.0000 1.0000
16.2800 92.0000 1.0000
16.3400 81.0000 1.0000
16.4000 88.0000 1.0000
16.4600 95.0000 1.0000
16.5200 134.0000 1.0000
16.5800 99.0000 1.0000
16.6400 100.0000 1.0000
16.7000 101.0000 1.0000
16.7600 87.0000 1.0000
16.8200 108.0000 1.0000
16.8800 94.0000 1.0000
16.9400 99.0000 1.0000
17.0000 120.0000 1.0000
17.0600 116.0000 1.0000
17.1200 96.0000 1.0000
17.1800 111.0000 1.0000
17.2400 82.0000 1.0000
17.3000 95.0000 1.0000
17.3600 84.0000 1.0000
17.4200 104.0000 1.0000
17.4800 87.0000 1.0000
17.5400 94.0000 1.0000
17.6000 92.0000 1.0000
17.6600 93.0000 1.0000
17.7200 85.0000 1.0000
17.7800 93.0000 1.0000
17.8400 91.0000 1.0000
17.9000 112.0000 1.0000
17.9600 80.0000 1.0000
18.0200 95.0000 1.0000
18.0800 102.0000 1.0000
18.1400 98.0000 1.0000
18.2000 85.0000 1.0000
18.2600 81.0000 1.0000
18.3200 76.0000 1.0000
18.3800 62.0000 1.0000
18.4400 62.0000 1.0000
18.5000 96.0000 1.0000
18.5600 89.0000 1.0000
18.6200 77.0000 1.0000
18.6800 71.0000 1.0000
18.7400 82.0000 1.0000
18.8000 93.0000 1.0000
18.8600 83.0000 1.0000
18.9200 74.0000 1.0000
18.9800 73.0000 1.0000
19.0400 92.0000 1.0000
19.1000 77.0000 1.0000
19.1600 91.0000 1.0000
19.2200 83.0000 1.0000
19.2800 93.0000 1.0000
19.3400 95.0000 1.0000
19.4000 47.0000 1.0000
19.4600 76.0000 1.0000
19.5200 83.0000 1.0000
19.5800 88.0000 1.0000
19.6400 71.0000 1.0000
19.7000 70.0000 1.0000
19.7600 96.0000 1.0000
19.8200 88.0000 1.0000
19.8800 73.0000 1.0000
19.9400 67.0000 1.0000
20.0000 75.0000 1.0000
20.0600 84.0000 1.0000
20.1200 55.0000 1.0000
20.1800 105.0000 1.0000
20.2400 93.0000 1.0000
20.3000 81.0000 1.0000
20.3600 87.0000 1.0000
20.4200 71.0000 1.0000
20.4800 88.0000 1.0000
20.5400 96.0000 1.0000
20.6000 63.0000 1.0000
20.6600 73.0000 1.0000
20.7200 82.0000 1.0000
20.7800 80.0000 1.0000
20.8400 65.0000 1.0000
20.9000 80.0000 1.0000
20.9600 89.0000 1.0000
21.0200 56.0000 1.0000
21.0800 80.0000 1.0000
21.1400 74.0000 1.0000
21.2000 68.0000 1.0000
21.2600 74.0000 1.0000
21.3200 64.0000 1.0000
21.3800 68.0000 1.0000
21.4400 84.0000 1.0000
21.5000 82.0000 1.0000
21.5600 72.0000 1.0000
21.6200 62.0000 1.0000
21.6800 64.0000 1.0000
21.7400 65.0000 1.0000
21.8000 68.0000 1.0000
21.8600 63.0000 1.0000
21.9200 77.0000 1.0000
21.9800 73.0000 1.0000
22.0400 50.0000 1.0000
22.1000 50.0000 1.0000
22.1600 69.0000 1.0000
22.2200 69.0000 1.0000
22.2800 90.0000 1.0000
22.3400 66.0000 1.0000
22.4000 60.0000 1.0000
22.4600 70.0000 1.0000
22.5200 59.0000 1.0000
22.5800 53.0000 1.0000
22.6400 55.0000 1.0000
22.7000 66.0000 1.0000
22.7600 54.0000 1.0000
22.8200 63.0000 1.0000
22.8800 58.0000 1.0000
22.9400 60.0000 1.0000
23.0000 70.0000 1.0000
23.0600 55.0000 1.0000
23.1200 61.0000 1.0000
23.1800 51.0000 1.0000
23.2400 53.0000 1.0000
23.3000 58.0000 1.0000
23.3600 58.0000 1.0000
23.4200 62.0000 1.0000
23.4800 46.0000 1.0000
23.5400 71.0000 1.0000
23.6000 59.0000 1.0000
23.6600 61.0000 1.0000
23.7200 62.0000 1.0000
23.7800 62.0000 1.0000
23.8400 53.0000 1.0000
23.9000 55.0000 1.0000
23.9600 61.0000 1.0000
24.0200 44.0000 1.0000
24.0800 48.0000 1.0000
24.1400 56.0000 1.0000
24.2000 72.0000 1.0000
24.2600 54.0000 1.0000
24.3200 45.0000 1.0000
24.3800 47.0000 1.0000
24.4400 68.0000 1.0000
24.5000 55.0000 1.0000
24.5600 60.0000 1.0000
24.6200 62.0000 1.0000
24.6800 62.0000 1.0000
24.7400 42.0000 1.0000
24.8000 39.0000 1.0000
24.8600 56.0000 1.0000
24.9200 43.0000 1.0000
24.9800 53.0000 1.0000
25.0400 56.0000 1.0000
25.1000 50.0000 1.0000
25.1600 44.0000 1.0000
25.2200 50.0000 1.0000
25.2800 63.0000 1.0000
25.3400 56.0000 1.0000
25.4000 55.0000 1.0000
25.4600 52.0000 1.0000
25.5200 50.0000 1.0000
25.5800 57.0000 1.0000
25.6400 44.0000 1.0000
25.7000 46.0000 1.0000
25.7600 40.0000 1.0000
25.8200 36.0000 1.0000
25.8800 51.0000 1.0000
25.9400 54.0000 1.0000
26.0000 58.0000 1.0000
26.0600 56.0000 1.0000
26.1200 69.0000 1.0000
26.1800 58.0000 1.0000
26.2400 52.0000 1.0000
26.3000 47.0000 1.0000
26.3600 56.0000 1.0000
26.4200 52.0000 1.0000
26.4800 55.0000 1.0000
26.5400 56.0000 1.0000
26.6000 57.0000 1.0000
26.6600 63.0000 1.0000
26.7200 91.0000 1.0000
26.7800 168.0000 1.0000
26.8400 116.0000 1.0000
26.9000 61.0000 1.0000
26.9600 52.0000 1.0000
27.0200 51.0000 1.0000
27.0800 61.0000 1.0000
27.1400 47.0000 1.0000
27.2000 44.0000 1.0000
27.2600 46.0000 1.0000
27.3200 44.0000 1.0000
27.3800 40.0000 1.0000
27.4400 50.0000 1.0000
27.5000 37.0000 1.0000
27.5600 54.0000 1.0000
27.6200 65.0000 1.0000
27.6800 50.0000 1.0000
27.7400 52.0000 1.0000
27.8000 65.0000 1.0000
27.8600 43.0000 1.0000
27.9200 37.0000 1.0000
27.9800 49.0000 1.0000
28.0400 48.0000 1.0000
28.1000 41.0000 1.0000
28.1600 46.0000 1.0000
28.2200 49.0000 1.0000
28.2800 49.0000 1.0000
28.3400 37.0000 1.0000
28.4000 43.0000 1.0000
28.4600 34.0000 1.0000
28.5200 41.0000 1.0000
28.5800 55.0000 1.0000
28.6400 42.0000 1.0000
28.7000 38.0000 1.0000
28.7600 38.0000 1.0000
28.8200 48.0000 1.0000
28.8800 49.0000 1.0000
28.9400 47.0000 1.0000
29.0000 51.0000 1.0000
29.0600 51.0000 1.0000
29.1200 51.0000 1.0000
29.1800 44.0000 1.0000
29.2400 60.0000 1.0000
29.3000 49.0000 1.0000
29.3600 48.0000 1.0000
29.4200 51.0000 1.0000
29.4800 48.0000 1.0000
29.5400 50.0000 1.0000
29.6000 43.0000 1.0000
29.6600 52.0000 1.0000
29.7200 46.0000 1.0000
29.7800 46.0000 1.0000
29.8400 47.0000 1.0000
29.9000 52.0000 1.0000
29.9600 57.0000 1.0000
30.0200 53.0000 1.0000
30.0800 53.0000 1.0000
30.1400 34.0000 1.0000
30.2000 53.0000 1.0000
30.2600 52.0000 1.0000
30.3200 65.0000 1.0000
30.3800 60.0000 1.0000
30.4400 86.0000 1.0000
30.5000 93.0000 1.0000
30.5600 309.0000 1.0000
30.6200 1552.0000 1.0000
30.6800 604.0000 1.0000
30.7400 485.0000 1.0000
30.8000 160.0000 1.0000
30.8600 108.0000 1.0000
30.9200 63.0000 1.0000
30.9800 49.0000 1.0000
31.0400 59.0000 1.0000
31.1000 48.0000 1.0000
31.1600 43.0000 1.0000
31.2200 41.0000 1.0000
31.2800 43.0000 1.0000
31.3400 46.0000 1.0000
31.4000 46.0000 1.0000
31.4600 43.0000 1.0000
31.5200 43.0000 1.0000
31.5800 41.0000 1.0000
31.6400 44.0000 1.0000
31.7000 35.0000 1.0000
31.7600 40.0000 1.0000
31.8200 32.0000 1.0000
31.8800 53.0000 1.0000
31.9400 40.0000 1.0000
32.0000 40.0000 1.0000
32.0600 45.0000 1.0000
32.1200 39.0000 1.0000
32.1800 50.0000 1.0000
32.2400 55.0000 1.0000
32.3000 41.0000 1.0000
32.3600 51.0000 1.0000
32.4200 53.0000 1.0000
32.4800 42.0000 1.0000
32.5400 40.0000 1.0000
32.6000 48.0000 1.0000
32.6600 41.0000 1.0000
32.7200 57.0000 1.0000
32.7800 51.0000 1.0000
32.8400 52.0000 1.0000
32.9000 95.0000 1.0000
32.9600 131.0000 1.0000
33.0200 87.0000 1.0000
33.0800 40.0000 1.0000
33.1400 42.0000 1.0000
33.2000 33.0000 1.0000
33.2600 49.0000 1.0000
33.3200 38.0000 1.0000
33.3800 42.0000 1.0000
33.4400 35.0000 1.0000
33.5000 42.0000 1.0000
33.5600 35.0000 1.0000
33.6200 34.0000 1.0000
33.6800 43.0000 1.0000
33.7400 37.0000 1.0000
33.8000 37.0000 1.0000
33.8600 41.0000 1.0000
33.9200 32.0000 1.0000
33.9800 50.0000 1.0000
34.0400 42.0000 1.0000
34.1000 45.0000 1.0000
34.1600 46.0000 1.0000
34.2200 34.0000 1.0000
34.2800 34.0000 1.0000
34.3400 37.0000 1.0000
34.4000 34.0000 1.0000
34.4600 37.0000 1.0000
34.5200 33.0000 1.0000
34.5800 41.0000 1.0000
34.6400 30.0000 1.0000
34.7000 33.0000 1.0000
34.7600 32.0000 1.0000
34.8200 34.0000 1.0000
34.8800 38.0000 1.0000
34.9400 31.0000 1.0000
35.0000 30.0000 1.0000
35.0600 38.0000 1.0000
35.1200 36.0000 1.0000
35.1800 38.0000 1.0000
35.2400 34.0000 1.0000
35.3000 33.0000 1.0000
35.3600 30.0000 1.0000
35.4200 44.0000 1.0000
35.4800 29.0000 1.0000
35.5400 40.0000 1.0000
35.6000 30.0000 1.0000
35.6600 44.0000 1.0000
35.7200 36.0000 1.0000
35.7800 34.0000 1.0000
35.8400 54.0000 1.0000
35.9000 35.0000 1.0000
35.9600 33.0000 1.0000
36.0200 32.0000 1.0000
36.0800 37.0000 1.0000
36.1400 47.0000 1.0000
36.2000 37.0000 1.0000
36.2600 38.0000 1.0000
36.3200 38.0000 1.0000
36.3800 32.0000 1.0000
36.4400 39.0000 1.0000
36.5000 36.0000 1.0000
36.5600 37.0000 1.0000
36.6200 38.0000 1.0000
36.6800 36.0000 1.0000
36.7400 35.0000 1.0000
36.8000 33.0000 1.0000
36.8600 40.0000 1.0000
36.9200 33.0000 1.0000
36.9800 38.0000 1.0000
37.0400 29.0000 1.0000
37.1000 34.0000 1.0000
37.1600 32.0000 1.0000
37.2200 33.0000 1.0000
37.2800 31.0000 1.0000
37.3400 34.0000 1.0000
37.4000 37.0000 1.0000
37.4600 56.0000 1.0000
37.5200 68.0000 1.0000
37.5800 30.0000 1.0000
37.6400 31.0000 1.0000
37.7000 32.0000 1.0000
37.7600 36.0000 1.0000
37.8200 43.0000 1.0000
37.8800 37.0000 1.0000
37.9400 47.0000 1.0000
38.0000 35.0000 1.0000
38.0600 29.0000 1.0000
38.1200 25.0000 1.0000
38.1800 52.0000 1.0000
38.2400 40.0000 1.0000
38.3000 37.0000 1.0000
38.3600 40.0000 1.0000
38.4200 34.0000 1.0000
38.4800 30.0000 1.0000
38.5400 28.0000 1.0000
38.6000 16.0000 1.0000
38.6600 40.0000 1.0000
38.7200 38.0000 1.0000
38.7800 31.0000 1.0000
38.8400 38.0000 1.0000
38.9000 45.0000 1.0000
38.9600 30.0000 1.0000
39.0200 29.0000 1.0000
39.0800 35.0000 1.0000
39.1400 30.0000 1.0000
39.2000 43.0000 1.0000
39.2600 40.0000 1.0000
39.3200 29.0000 1.0000
39.3800 40.0000 1.0000
39.4400 42.0000 1.0000
39.5000 46.0000 1.0000
39.5600 46.0000 1.0000
39.6200 40.0000 1.0000
39.6800 29.0000 1.0000
39.7400 27.0000 1.0000
39.8000 39.0000 1.0000
39.8600 39.0000 1.0000
39.9200 38.0000 1.0000
39.9800 31.0000 1.0000
40.0400 40.0000 1.0000
40.1000 34.0000 1.0000
40.1600 33.0000 1.0000
40.2200 37.0000 1.0000
40.2800 44.0000 1.0000
40.3400 34.0000 1.0000
40.4000 44.0000 1.0000
40.4600 39.0000 1.0000
40.5200 55.0000 1.0000
40.5800 42.0000 1.0000
40.6400 38.0000 1.0000
40.7000 39.0000 1.0000
40.7600 31.0000 1.0000
40.8200 41.0000 1.0000
40.8800 38.0000 1.0000
40.9400 42.0000 1.0000
41.0000 40.0000 1.0000
41.0600 37.0000 1.0000
41.1200 36.0000 1.0000
41.1800 42.0000 1.0000
41.2400 41.0000 1.0000
41.3000 51.0000 1.0000
41.3600 43.0000 1.0000
41.4200 57.0000 1.0000
41.4800 83.0000 1.0000
41.5400 97.0000 1.0000
41.6000 239.0000 1.0000
41.6600 1635.0000 1.0000
41.7200 758.0000 1.0000
41.7800 1003.0000 1.0000
41.8400 260.0000 1.0000
41.9000 105.0000 1.0000
41.9600 79.0000 1.0000
42.0200 55.0000 1.0000
42.0800 36.0000 1.0000
42.1400 41.0000 1.0000
42.2000 41.0000 1.0000
42.2600 56.0000 1.0000
42.3200 70.0000 1.0000
42.3800 81.0000 1.0000
42.4400 109.0000 1.0000
42.5000 85.0000 1.0000
42.5600 90.0000 1.0000
42.6200 137.0000 1.0000
42.6800 122.0000 1.0000
42.7400 116.0000 1.0000
42.8000 115.0000 1.0000
42.8600 223.0000 1.0000
42.9200 439.0000 1.0000
42.9800 330.0000 1.0000
43.0400 247.0000 1.0000
43.1000 120.0000 1.0000
43.1600 56.0000 1.0000
43.2200 60.0000 1.0000
43.2800 52.0000 1.0000
43.3400 45.0000 1.0000
43.4000 38.0000 1.0000
43.4600 58.0000 1.0000
43.5200 72.0000 1.0000
43.5800 73.0000 1.0000
43.6400 103.0000 1.0000
43.7000 142.0000 1.0000
43.7600 411.0000 1.0000
43.8200 1064.0000 1.0000
43.8800 982.0000 1.0000
43.9400 743.0000 1.0000
44.0000 442.0000 1.0000
44.0600 163.0000 1.0000
44.1200 72.0000 1.0000
44.1800 56.0000 1.0000
44.2400 59.0000 1.0000
44.3000 40.0000 1.0000
44.3600 33.0000 1.0000
44.4200 49.0000 1.0000
44.4800 37.0000 1.0000
44.5400 50.0000 1.0000
44.6000 43.0000 1.0000
44.6600 46.0000 1.0000
44.7200 30.0000 1.0000
44.7800 35.0000 1.0000
44.8400 32.0000 1.0000
44.9000 35.0000 1.0000
44.9600 33.0000 1.0000
45.0200 25.0000 1.0000
45.0800 45.0000 1.0000
45.1400 35.0000 1.0000
45.2000 34.0000 1.0000
45.2600 42.0000 1.0000
45.3200 40.0000 1.0000
45.3800 45.0000 1.0000
45.4400 47.0000 1.0000
45.5000 47.0000 1.0000
45.5600 45.0000 1.0000
45.6200 36.0000 1.0000
45.6800 35.0000 1.0000
45.7400 32.0000 1.0000
45.8000 32.0000 1.0000
45.8600 41.0000 1.0000
45.9200 34.0000 1.0000
45.9800 38.0000 1.0000
46.0400 39.0000 1.0000
46.1000 34.0000 1.0000
46.1600 35.0000 1.0000
46.2200 33.0000 1.0000
46.2800 28.0000 1.0000
46.3400 44.0000 1.0000
46.4000 34.0000 1.0000
46.4600 34.0000 1.0000
46.5200 46.0000 1.0000
46.5800 51.0000 1.0000
46.6400 44.0000 1.0000
46.7000 61.0000 1.0000
46.7600 56.0000 1.0000
46.8200 68.0000 1.0000
46.8800 85.0000 1.0000
46.9400 97.0000 1.0000
47.0000 84.0000 1.0000
47.0600 83.0000 1.0000
47.1200 76.0000 1.0000
47.1800 94.0000 1.0000
47.2400 282.0000 1.0000
47.3000 181.0000 1.0000
47.3600 146.0000 1.0000
47.4200 120.0000 1.0000
47.4800 57.0000 1.0000
47.5400 39.0000 1.0000
47.6000 40.0000 1.0000
47.6600 38.0000 1.0000
47.7200 44.0000 1.0000
47.7800 29.0000 1.0000
47.8400 34.0000 1.0000
47.9000 32.0000 1.0000
47.9600 27.0000 1.0000
48.0200 29.0000 1.0000
48.0800 51.0000 1.0000
48.1400 64.0000 1.0000
48.2000 94.0000 1.0000
48.2600 48.0000 1.0000
48.3200 40.0000 1.0000
48.3800 40.0000 1.0000
48.4400 39.0000 1.0000
48.5000 38.0000 1.0000
48.5600 33.0000 1.0000
48.6200 24.0000 1.0000
48.6800 31.0000 1.0000
48.7400 49.0000 1.0000
48.8000 36.0000 1.0000
48.8600 20.0000 1.0000
48.9200 40.0000 1.0000
48.9800 35.0000 1.0000
49.0400 33.0000 1.0000
49.1000 31.0000 1.0000
49.1600 38.0000 1.0000
49.2200 29.0000 1.0000
49.2800 30.0000 1.0000
49.3400 35.0000 1.0000
49.4000 35.0000 1.0000
49.4600 36.0000 1.0000
49.5200 34.0000 1.0000
49.5800 31.0000 1.0000
49.6400 27.0000 1.0000
49.7000 28.0000 1.0000
49.7600 40.0000 1.0000
49.8200 27.0000 1.0000
49.8800 28.0000 1.0000
49.9400 32.0000 1.0000
50.0000 30.0000 1.0000
50.0600 25.0000 1.0000
50.1200 46.0000 1.0000
50.1800 30.0000 1.0000
50.2400 31.0000 1.0000
50.3000 25.0000 1.0000
50.3600 24.0000 1.0000
50.4200 36.0000 1.0000
50.4800 31.0000 1.0000
50.5400 27.0000 1.0000
50.6000 40.0000 1.0000
50.6600 29.0000 1.0000
50.7200 28.0000 1.0000
50.7800 36.0000 1.0000
50.8400 26.0000 1.0000
50.9000 30.0000 1.0000
50.9600 24.0000 1.0000
51.0200 24.0000 1.0000
51.0800 37.0000 1.0000
51.1400 29.0000 1.0000
51.2000 36.0000 1.0000
51.2600 31.0000 1.0000
51.3200 43.0000 1.0000
51.3800 45.0000 1.0000
51.4400 32.0000 1.0000
51.5000 37.0000 1.0000
51.5600 34.0000 1.0000
51.6200 45.0000 1.0000
51.6800 35.0000 1.0000
51.7400 36.0000 1.0000
51.8000 37.0000 1.0000
51.8600 44.0000 1.0000
51.9200 43.0000 1.0000
51.9800 49.0000 1.0000
52.0400 54.0000 1.0000
52.1000 62.0000 1.0000
52.1600 43.0000 1.0000
52.2200 50.0000 1.0000
52.2800 54.0000 1.0000
52.3400 47.0000 1.0000
52.4000 42.0000 1.0000
52.4600 46.0000 1.0000
52.5200 53.0000 1.0000
52.5800 51.0000 1.0000
52.6400 50.0000 1.0000
52.7000 44.0000 1.0000
52.7600 45.0000 1.0000
52.8200 56.0000 1.0000
52.8800 48.0000 1.0000
52.9400 47.0000 1.0000
53.0000 50.0000 1.0000
53.0600 51.0000 1.0000
53.1200 60.0000 1.0000
53.1800 57.0000 1.0000
53.2400 69.0000 1.0000
53.3000 53.0000 1.0000
53.3600 98.0000 1.0000
53.4200 164.0000 1.0000
53.4800 327.0000 1.0000
53.5400 487.0000 1.0000
53.6000 917.0000 1.0000
53.6600 2501.0000 1.0000
53.7200 7195.0000 1.0000
53.7800 3299.0000 1.0000
53.8400 3137.0000 1.0000
53.9000 2685.0000 1.0000
53.9600 588.0000 1.0000
54.0200 203.0000 1.0000
54.0800 142.0000 1.0000
54.1400 100.0000 1.0000
54.2000 68.0000 1.0000
54.2600 77.0000 1.0000
54.3200 72.0000 1.0000
54.3800 85.0000 1.0000
54.4400 92.0000 1.0000
54.5000 76.0000 1.0000
54.5600 77.0000 1.0000
54.6200 70.0000 1.0000
54.6800 54.0000 1.0000
54.7400 50.0000 1.0000
54.8000 52.0000 1.0000
54.8600 46.0000 1.0000
54.9200 37.0000 1.0000
54.9800 49.0000 1.0000
55.0400 52.0000 1.0000
55.1000 44.0000 1.0000
55.1600 53.0000 1.0000
55.2200 36.0000 1.0000
55.2800 39.0000 1.0000
55.3400 29.0000 1.0000
55.4000 33.0000 1.0000
55.4600 40.0000 1.0000
55.5200 39.0000 1.0000
55.5800 40.0000 1.0000
55.6400 39.0000 1.0000
55.7000 44.0000 1.0000
55.7600 27.0000 1.0000
55.8200 28.0000 1.0000
55.8800 38.0000 1.0000
55.9400 36.0000 1.0000
56.0000 41.0000 1.0000
56.0600 33.0000 1.0000
56.1200 25.0000 1.0000
56.1800 36.0000 1.0000
56.2400 28.0000 1.0000
56.3000 31.0000 1.0000
56.3600 42.0000 1.0000
56.4200 37.0000 1.0000
56.4800 30.0000 1.0000
56.5400 43.0000 1.0000
56.6000 49.0000 1.0000
56.6600 30.0000 1.0000
56.7200 29.0000 1.0000
56.7800 42.0000 1.0000
56.8400 29.0000 1.0000
56.9000 31.0000 1.0000
56.9600 34.0000 1.0000
57.0200 52.0000 1.0000
57.0800 38.0000 1.0000
57.1400 37.0000 1.0000
57.2000 31.0000 1.0000
57.2600 42.0000 1.0000
57.3200 40.0000 1.0000
57.3800 43.0000 1.0000
57.4400 50.0000 1.0000
57.5000 32.0000 1.0000
57.5600 38.0000 1.0000
57.6200 40.0000 1.0000
57.6800 31.0000 1.0000
57.7400 35.0000 1.0000
57.8000 49.0000 1.0000
57.8600 42.0000 1.0000
57.9200 34.0000 1.0000
57.9800 37.0000 1.0000
58.0400 34.0000 1.0000
58.1000 34.0000 1.0000
58.1600 34.0000 1.0000
58.2200 35.0000 1.0000
58.2800 35.0000 1.0000
58.3400 45.0000 1.0000
58.4000 40.0000 1.0000
58.4600 32.0000 1.0000
58.5200 33.0000 1.0000
58.5800 38.0000 1.0000
58.6400 36.0000 1.0000
58.7000 36.0000 1.0000
58.7600 35.0000 1.0000
58.8200 43.0000 1.0000
58.8800 42.0000 1.0000
58.9400 43.0000 1.0000
59.0000 45.0000 1.0000
59.0600 33.0000 1.0000
59.1200 44.0000 1.0000
59.1800 38.0000 1.0000
59.2400 34.0000 1.0000
59.3000 34.0000 1.0000
59.3600 52.0000 1.0000
59.4200 32.0000 1.0000
59.4800 35.0000 1.0000
59.5400 34.0000 1.0000
59.6000 34.0000 1.0000
59.6600 30.0000 1.0000
59.7200 32.0000 1.0000
59.7800 25.0000 1.0000
59.8400 43.0000 1.0000
59.9000 42.0000 1.0000
59.9600 26.0000 1.0000
60.0200 30.0000 1.0000
60.0800 25.0000 1.0000
60.1400 31.0000 1.0000
60.2000 33.0000 1.0000
60.2600 26.0000 1.0000
60.3200 33.0000 1.0000
60.3800 38.0000 1.0000
60.4400 26.0000 1.0000
60.5000 29.0000 1.0000
60.5600 35.0000 1.0000
60.6200 42.0000 1.0000
60.6800 27.0000 1.0000
60.7400 23.0000 1.0000
60.8000 43.0000 1.0000
60.8600 32.0000 1.0000
60.9200 33.0000 1.0000
60.9800 35.0000 1.0000
61.0400 40.0000 1.0000
61.1000 32.0000 1.0000
61.1600 40.0000 1.0000
61.2200 32.0000 1.0000
61.2800 37.0000 1.0000
61.3400 39.0000 1.0000
61.4000 25.0000 1.0000
61.4600 41.0000 1.0000
61.5200 27.0000 1.0000
61.5800 49.0000 1.0000
61.6400 38.0000 1.0000
61.7000 33.0000 1.0000
61.7600 58.0000 1.0000
61.8200 37.0000 1.0000
61.8800 39.0000 1.0000
61.9400 57.0000 1.0000
62.0000 43.0000 1.0000
62.0600 34.0000 1.0000
62.1200 48.0000 1.0000
62.1800 63.0000 1.0000
62.2400 63.0000 1.0000
62.3000 66.0000 1.0000
62.3600 74.0000 1.0000
62.4200 54.0000 1.0000
62.4800 55.0000 1.0000
62.5400 56.0000 1.0000
62.6000 58.0000 1.0000
62.6600 32.0000 1.0000
62.7200 43.0000 1.0000
62.7800 37.0000 1.0000
62.8400 37.0000 1.0000
62.9000 40.0000 1.0000
62.9600 33.0000 1.0000
63.0200 53.0000 1.0000
63.0800 43.0000 1.0000
63.1400 59.0000 1.0000
63.2000 50.0000 1.0000
63.2600 46.0000 1.0000
63.3200 46.0000 1.0000
63.3800 54.0000 1.0000
63.4400 48.0000 1.0000
63.5000 73.0000 1.0000
63.5600 82.0000 1.0000
63.6200 139.0000 1.0000
63.6800 313.0000 1.0000
63.7400 1171.0000 1.0000
63.8000 421.0000 1.0000
63.8600 272.0000 1.0000
63.9200 677.0000 1.0000
63.9800 326.0000 1.0000
64.0400 569.0000 1.0000
64.1000 873.0000 1.0000
64.1600 445.0000 1.0000
64.2200 394.0000 1.0000
64.2800 465.0000 1.0000
64.3400 232.0000 1.0000
64.4000 94.0000 1.0000
64.4600 62.0000 1.0000
64.5200 55.0000 1.0000
64.5800 59.0000 1.0000
64.6400 55.0000 1.0000
64.7000 58.0000 1.0000
64.7600 41.0000 1.0000
64.8200 48.0000 1.0000
64.8800 50.0000 1.0000
64.9400 50.0000 1.0000
65.0000 30.0000 1.0000
65.0600 42.0000 1.0000
65.1200 43.0000 1.0000
65.1800 50.0000 1.0000
65.2400 39.0000 1.0000
65.3000 48.0000 1.0000
65.3600 55.0000 1.0000
65.4200 51.0000 1.0000
65.4800 48.0000 1.0000
65.5400 60.0000 1.0000
65.6000 73.0000 1.0000
65.6600 76.0000 1.0000
65.7200 80.0000 1.0000
65.7800 83.0000 1.0000
65.8400 57.0000 1.0000
65.9000 62.0000 1.0000
65.9600 64.0000 1.0000
66.0200 27.0000 1.0000
66.0800 45.0000 1.0000
66.1400 31.0000 1.0000
66.2000 41.0000 1.0000
66.2600 41.0000 1.0000
66.3200 36.0000 1.0000
66.3800 41.0000 1.0000
66.4400 34.0000 1.0000
66.5000 36.0000 1.0000
66.5600 48.0000 1.0000
66.6200 48.0000 1.0000
66.6800 37.0000 1.0000
66.7400 45.0000 1.0000
66.8000 46.0000 1.0000
66.8600 34.0000 1.0000
66.9200 40.0000 1.0000
66.9800 36.0000 1.0000
67.0400 41.0000 1.0000
67.1000 46.0000 1.0000
67.1600 48.0000 1.0000
67.2200 51.0000 1.0000
67.2800 36.0000 1.0000
67.3400 41.0000 1.0000
67.4000 41.0000 1.0000
67.4600 45.0000 1.0000
67.5200 33.0000 1.0000
67.5800 46.0000 1.0000
67.6400 41.0000 1.0000
67.7000 34.0000 1.0000
67.7600 37.0000 1.0000
67.8200 40.0000 1.0000
67.8800 37.0000 1.0000
67.9400 34.0000 1.0000
68.0000 45.0000 1.0000
68.0600 33.0000 1.0000
68.1200 41.0000 1.0000
68.1800 38.0000 1.0000
68.2400 40.0000 1.0000
68.3000 38.0000 1.0000
68.3600 45.0000 1.0000
68.4200 48.0000 1.0000
68.4800 37.0000 1.0000
68.5400 47.0000 1.0000
68.6000 37.0000 1.0000
68.6600 39.0000 1.0000
68.7200 50.0000 1.0000
68.7800 50.0000 1.0000
68.8400 44.0000 1.0000
68.9000 45.0000 1.0000
68.9600 55.0000 1.0000
69.0200 62.0000 1.0000
69.0800 75.0000 1.0000
69.1400 46.0000 1.0000
69.2000 42.0000 1.0000
69.2600 49.0000 1.0000
69.3200 63.0000 1.0000
69.3800 47.0000 1.0000
69.4400 27.0000 1.0000
69.5000 27.0000 1.0000
69.5600 40.0000 1.0000
69.6200 31.0000 1.0000
69.6800 36.0000 1.0000
69.7400 35.0000 1.0000
69.8000 28.0000 1.0000
69.8600 32.0000 1.0000
69.9200 43.0000 1.0000
69.9800 42.0000 1.0000
70.0400 29.0000 1.0000
70.1000 28.0000 1.0000
70.1600 31.0000 1.0000
70.2200 44.0000 1.0000
70.2800 37.0000 1.0000
70.3400 45.0000 1.0000
70.4000 24.0000 1.0000
70.4600 37.0000 1.0000
70.5200 32.0000 1.0000
70.5800 47.0000 1.0000
70.6400 38.0000 1.0000
70.7000 51.0000 1.0000
70.7600 36.0000 1.0000
70.8200 33.0000 1.0000
70.8800 45.0000 1.0000
70.9400 41.0000 1.0000
71.0000 40.0000 1.0000
71.0600 42.0000 1.0000
71.1200 36.0000 1.0000
71.1800 46.0000 1.0000
71.2400 39.0000 1.0000
71.3000 33.0000 1.0000
71.3600 47.0000 1.0000
71.4200 53.0000 1.0000
71.4800 56.0000 1.0000
71.5400 53.0000 1.0000
71.6000 48.0000 1.0000
71.6600 46.0000 1.0000
71.7200 44.0000 1.0000
71.7800 48.0000 1.0000
71.8400 49.0000 1.0000
71.9000 62.0000 1.0000
71.9600 53.0000 1.0000
72.0200 66.0000 1.0000
72.0800 68.0000 1.0000
72.1400 81.0000 1.0000
72.2000 88.0000 1.0000
72.2600 133.0000 1.0000
72.3200 168.0000 1.0000
72.3800 182.0000 1.0000
72.4400 140.0000 1.0000
72.5000 101.0000 1.0000
72.5600 104.0000 1.0000
72.6200 87.0000 1.0000
72.6800 62.0000 1.0000
72.7400 32.0000 1.0000
72.8000 34.0000 1.0000
72.8600 50.0000 1.0000
72.9200 49.0000 1.0000
72.9800 47.0000 1.0000
73.0400 44.0000 1.0000
73.1000 51.0000 1.0000
73.1600 36.0000 1.0000
73.2200 42.0000 1.0000
73.2800 52.0000 1.0000
73.3400 43.0000 1.0000
73.4000 48.0000 1.0000
73.4600 69.0000 1.0000
73.5200 73.0000 1.0000
73.5800 141.0000 1.0000
73.6400 159.0000 1.0000
73.7000 91.0000 1.0000
73.7600 111.0000 1.0000
73.8200 129.0000 1.0000
73.8800 114.0000 1.0000
73.9400 100.0000 1.0000
74.0000 73.0000 1.0000
74.0600 48.0000 1.0000
74.1200 69.0000 1.0000
74.1800 74.0000 1.0000
74.2400 50.0000 1.0000
74.3000 37.0000 1.0000
74.3600 44.0000 1.0000
74.4200 54.0000 1.0000
74.4800 48.0000 1.0000
74.5400 39.0000 1.0000
74.6000 40.0000 1.0000
74.6600 42.0000 1.0000
74.7200 42.0000 1.0000
74.7800 40.0000 1.0000
74.8400 40.0000 1.0000
74.9000 45.0000 1.0000
74.9600 42.0000 1.0000
75.0200 55.0000 1.0000
75.0800 73.0000 1.0000
75.1400 70.0000 1.0000
75.2000 79.0000 1.0000
75.2600 91.0000 1.0000
75.3200 86.0000 1.0000
75.3800 107.0000 1.0000
75.4400 177.0000 1.0000
75.5000 179.0000 1.0000
75.5600 162.0000 1.0000
75.6200 105.0000 1.0000
75.6800 106.0000 1.0000
75.7400 103.0000 1.0000
75.8000 69.0000 1.0000
75.8600 58.0000 1.0000
75.9200 48.0000 1.0000
75.9800 33.0000 1.0000
76.0400 31.0000 1.0000
76.1000 52.0000 1.0000
76.1600 44.0000 1.0000
76.2200 48.0000 1.0000
76.2800 40.0000 1.0000
76.3400 45.0000 1.0000
76.4000 39.0000 1.0000
76.4600 48.0000 1.0000
76.5200 48.0000 1.0000
76.5800 57.0000 1.0000
76.6400 55.0000 1.0000
76.7000 34.0000 1.0000
76.7600 58.0000 1.0000
76.8200 66.0000 1.0000
76.8800 92.0000 1.0000
76.9400 174.0000 1.0000
77.0000 275.0000 1.0000
77.0600 200.0000 1.0000
77.1200 115.0000 1.0000
77.1800 146.0000 1.0000
77.2400 140.0000 1.0000
77.3000 98.0000 1.0000
77.3600 54.0000 1.0000
77.4200 53.0000 1.0000
77.4800 41.0000 1.0000
77.5400 44.0000 1.0000
77.6000 34.0000 1.0000
77.6600 37.0000 1.0000
77.7200 34.0000 1.0000
77.7800 39.0000 1.0000
77.8400 47.0000 1.0000
77.9000 38.0000 1.0000
77.9600 36.0000 1.0000
78.0200 47.0000 1.0000
78.0800 37.0000 1.0000
78.1400 41.0000 1.0000
78.2000 33.0000 1.0000
78.2600 34.0000 1.0000
78.3200 39.0000 1.0000
78.3800 39.0000 1.0000
78.4400 31.0000 1.0000
78.5000 37.0000 1.0000
78.5600 38.0000 1.0000
78.6200 35.0000 1.0000
78.6800 32.0000 1.0000
78.7400 49.0000 1.0000
78.8000 53.0000 1.0000
78.8600 38.0000 1.0000
78.9200 76.0000 1.0000
78.9800 40.0000 1.0000
79.0400 32.0000 1.0000
79.1000 43.0000 1.0000
79.1600 50.0000 1.0000
79.2200 50.0000 1.0000
79.2800 64.0000 1.0000
79.3400 57.0000 1.0000
79.4000 61.0000 1.0000
79.4600 50.0000 1.0000
79.5200 62.0000 1.0000
79.5800 59.0000 1.0000
79.6400 50.0000 1.0000
79.7000 42.0000 1.0000
79.7600 40.0000 1.0000
79.8200 48.0000 1.0000
79.8800 59.0000 1.0000
79.9400 50.0000 1.0000
80.0000 57.0000 1.0000
80.0600 65.0000 1.0000
80.1200 89.0000 1.0000
80.1800 81.0000 1.0000
80.2400 99.0000 1.0000
80.3000 132.0000 1.0000
80.3600 216.0000 1.0000
80.4200 343.0000 1.0000
80.4800 703.0000 1.0000
80.5400 1140.0000 1.0000
80.6000 1415.0000 1.0000
80.6600 1012.0000 1.0000
80.7200 665.0000 1.0000
80.7800 706.0000 1.0000
80.8400 655.0000 1.0000
80.9000 464.0000 1.0000
80.9600 229.0000 1.0000
81.0200 126.0000 1.0000
81.0800 68.0000 1.0000
81.1400 61.0000 1.0000
81.2000 54.0000 1.0000
81.2600 64.0000 1.0000
81.3200 60.0000 1.0000
81.3800 53.0000 1.0000
81.4400 64.0000 1.0000
81.5000 52.0000 1.0000
81.5600 66.0000 1.0000
81.6200 64.0000 1.0000
81.6800 80.0000 1.0000
81.7400 79.0000 1.0000
81.8000 66.0000 1.0000
81.8600 61.0000 1.0000
81.9200 58.0000 1.0000
81.9800 50.0000 1.0000
82.0400 44.0000 1.0000
82.1000 48.0000 1.0000
82.1600 45.0000 1.0000
82.2200 47.0000 1.0000
82.2800 45.0000 1.0000
82.3400 54.0000 1.0000
82.4000 46.0000 1.0000
82.4600 49.0000 1.0000
82.5200 36.0000 1.0000
82.5800 36.0000 1.0000
82.6400 36.0000 1.0000
82.7000 48.0000 1.0000
82.7600 36.0000 1.0000
82.8200 36.0000 1.0000
82.8800 34.0000 1.0000
82.9400 37.0000 1.0000
83.0000 37.0000 1.0000
83.0600 43.0000 1.0000
83.1200 44.0000 1.0000
83.1800 46.0000 1.0000
83.2400 37.0000 1.0000
83.3000 53.0000 1.0000
83.3600 44.0000 1.0000
83.4200 48.0000 1.0000
83.4800 42.0000 1.0000
83.5400 43.0000 1.0000
83.6000 43.0000 1.0000
83.6600 35.0000 1.0000
83.7200 23.0000 1.0000
83.7800 36.0000 1.0000
83.8400 40.0000 1.0000
83.9000 44.0000 1.0000
83.9600 48.0000 1.0000
84.0200 40.0000 1.0000
84.0800 35.0000 1.0000
84.1400 49.0000 1.0000
84.2000 35.0000 1.0000
84.2600 41.0000 1.0000
84.3200 40.0000 1.0000
84.3800 56.0000 1.0000
84.4400 44.0000 1.0000
84.5000 37.0000 1.0000
84.5600 42.0000 1.0000
84.6200 38.0000 1.0000
84.6800 50.0000 1.0000
84.7400 46.0000 1.0000
84.8000 49.0000 1.0000
84.8600 55.0000 1.0000
84.9200 39.0000 1.0000
84.9800 52.0000 1.0000
85.0400 36.0000 1.0000
85.1000 41.0000 1.0000
85.1600 36.0000 1.0000
85.2200 44.0000 1.0000
85.2800 60.0000 1.0000
85.3400 52.0000 1.0000
85.4000 67.0000 1.0000
85.4600 40.0000 1.0000
85.5200 48.0000 1.0000
85.5800 53.0000 1.0000
85.6400 52.0000 1.0000
85.7000 46.0000 1.0000
85.7600 48.0000 1.0000
85.8200 44.0000 1.0000
85.8800 49.0000 1.0000
85.9400 63.0000 1.0000
86.0000 36.0000 1.0000
86.0600 50.0000 1.0000
86.1200 67.0000 1.0000
86.1800 155.0000 1.0000
86.2400 217.0000 1.0000
86.3000 174.0000 1.0000
86.3600 109.0000 1.0000
86.4200 99.0000 1.0000
86.4800 108.0000 1.0000
86.5400 147.0000 1.0000
86.6000 76.0000 1.0000
86.6600 62.0000 1.0000
86.7200 52.0000 1.0000
86.7800 38.0000 1.0000
86.8400 48.0000 1.0000
86.9000 36.0000 1.0000
86.9600 42.0000 1.0000
87.0200 51.0000 1.0000
87.0800 39.0000 1.0000
87.1400 38.0000 1.0000
87.2000 37.0000 1.0000
87.2600 50.0000 1.0000
87.3200 37.0000 1.0000
87.3800 53.0000 1.0000
87.4400 50.0000 1.0000
87.5000 38.0000 1.0000
87.5600 43.0000 1.0000
87.6200 55.0000 1.0000
87.6800 37.0000 1.0000
87.7400 70.0000 1.0000
87.8000 62.0000 1.0000
87.8600 66.0000 1.0000
87.9200 53.0000 1.0000
87.9800 65.0000 1.0000
88.0400 53.0000 1.0000
88.1000 53.0000 1.0000
88.1600 63.0000 1.0000
88.2200 55.0000 1.0000
88.2800 60.0000 1.0000
88.3400 42.0000 1.0000
88.4000 45.0000 1.0000
88.4600 47.0000 1.0000
88.5200 64.0000 1.0000
88.5800 41.0000 1.0000
88.6400 44.0000 1.0000
88.7000 39.0000 1.0000
88.7600 48.0000 1.0000
88.8200 63.0000 1.0000
88.8800 43.0000 1.0000
88.9400 43.0000 1.0000
89.0000 40.0000 1.0000
89.0600 42.0000 1.0000
89.1200 49.0000 1.0000
89.1800 48.0000 1.0000
89.2400 34.0000 1.0000
89.3000 39.0000 1.0000
89.3600 41.0000 1.0000
89.4200 31.0000 1.0000
89.4800 33.0000 1.0000
89.5400 36.0000 1.0000
89.6000 36.0000 1.0000
89.6600 48.0000 1.0000
89.7200 38.0000 1.0000
89.7800 51.0000 1.0000
89.8400 53.0000 1.0000
89.9000 64.0000 1.0000
89.9600 72.0000 1.0000
89.9800 78.0000 1.0000
*RAS_INT_END
*RAS_DATA_END